Workbook

Sheet Dashboard
B2: Research submissions
B3: ="As of "&TEXT(TODAY(),"d mmmm yyyy")&" · edit the Submissions and Papers sheets; this page updates itself" -> As of 11 October 2026 · edit the Submissions and Papers sheets; this page updates itself | J3: Chase editor after (days): | M3: 90
B5: PAPERS TRACKED | D5: WAITING ON YOU | F5: UNDER REVIEW | H5: REVISIONS DUE | J5: SUBMISSIONS SENT | L5: ACCEPTED
B6: =COUNTIFS(Papers!$A$2:$A$81,"<>",Papers!$F$2:$F$81,"<>Parked",Papers!$F$2:$F$81,"<>Closed – rejected",Papers!$F$2:$F$81,"<>Withdrawn",Papers!$F$2:$F$81,"<>Published") -> 16 | D6: =COUNTIF(Papers!$F$2:$F$81,"Revision due")+COUNTIF(Papers!$F$2:$F$81,"Needs resubmission")+COUNTIF(Papers!$F$2:$F$81,"Not yet submitted") -> 6 | F6: =COUNTIF(Papers!$F$2:$F$81,"Under review") -> 10 | H6: =COUNTIF(Papers!$F$2:$F$81,"Revision due") -> 0 | J6: =SUM(Submissions!$J$2:$J$1000) -> 84 | L6: =COUNTIF(Submissions!$D$2:$D$1000,"Accepted") -> 0
B7: excl. closed, parked, published | D7: to (re)submit or revise | F7: with a journal now | H7: decision: revise & resubmit | J7: =COUNTIFS(Submissions!$D$2:$D$1000,"Rejected")+COUNTIFS(Submissions!$D$2:$D$1000,"Returned by office")&" rejected or returned" -> 73 rejected or returned | L7: ="avg "&IFERROR(ROUND(AVERAGEIFS(Submissions!$G$2:$G$1000,Submissions!$F$2:$F$1000,"<>",Submissions!$J$2:$J$1000,1),0),"–")&" days to a decision" -> avg 36 days to a decision
B9: Waiting on you | H9: =IF(COUNT(Papers!$O$2:$O$81)>12,"showing top 12 of "&COUNT(Papers!$O$2:$O$81),"longest-idle first") -> longest-idle first
B10: PAPER | E10: STAGE | F10: LAST JOURNAL TRIED | I10: IDLE (DAYS) | J10: NEXT IN QUEUE
B11: =IF($O11="","",INDEX(Papers!$A$2:$A$81,$O11)&"") -> Trust by Design (India engagement) | E11: =IF($O11="","",INDEX(Papers!$F$2:$F$81,$O11)&"") -> Needs resubmission | F11: =IF($O11="","",INDEX(Papers!$G$2:$G$81,$O11)&"") -> Industrial and Commercial Training | I11: =IF($O11="","",INDEX(Papers!$I$2:$I$81,$O11)) -> 439 | J11: =IF($O11="","",INDEX(Papers!$J$2:$J$81,$O11)&"") -> Strategic HR Review | O11: =IFERROR(MATCH(1,Papers!$O$2:$O$81,0),"") -> 15
B12: =IF($O12="","",INDEX(Papers!$A$2:$A$81,$O12)&"") -> Cockroach Spoke Back (Instagram, irony) | E12: =IF($O12="","",INDEX(Papers!$F$2:$F$81,$O12)&"") -> Needs resubmission | F12: =IF($O12="","",INDEX(Papers!$G$2:$G$81,$O12)&"") -> Media, Culture & Society | I12: =IF($O12="","",INDEX(Papers!$I$2:$I$81,$O12)) -> 102 | J12: =IF($O12="","",INDEX(Papers!$J$2:$J$81,$O12)&"") | O12: =IFERROR(MATCH(2,Papers!$O$2:$O$81,0),"") -> 4
B13: =IF($O13="","",INDEX(Papers!$A$2:$A$81,$O13)&"") -> From Medium to Interlocutor (GenAI) | E13: =IF($O13="","",INDEX(Papers!$F$2:$F$81,$O13)&"") -> Needs resubmission | F13: =IF($O13="","",INDEX(Papers!$G$2:$G$81,$O13)&"") -> Information, Communication & Society | I13: =IF($O13="","",INDEX(Papers!$I$2:$I$81,$O13)) -> 1 | J13: =IF($O13="","",INDEX(Papers!$J$2:$J$81,$O13)&"") -> Journal of Computer-Mediated Communication | O13: =IFERROR(MATCH(3,Papers!$O$2:$O$81,0),"") -> 11
B14: =IF($O14="","",INDEX(Papers!$A$2:$A$81,$O14)&"") -> Distributed securitization (India SIR) | E14: =IF($O14="","",INDEX(Papers!$F$2:$F$81,$O14)&"") -> Not yet submitted | F14: =IF($O14="","",INDEX(Papers!$G$2:$G$81,$O14)&"") | I14: =IF($O14="","",INDEX(Papers!$I$2:$I$81,$O14)) | J14: =IF($O14="","",INDEX(Papers!$J$2:$J$81,$O14)&"") -> Security Studies | O14: =IFERROR(MATCH(4,Papers!$O$2:$O$81,0),"") -> 6
B15: =IF($O15="","",INDEX(Papers!$A$2:$A$81,$O15)&"") -> Right to the Secret (Blanchot–Heidegger) | E15: =IF($O15="","",INDEX(Papers!$F$2:$F$81,$O15)&"") -> Not yet submitted | F15: =IF($O15="","",INDEX(Papers!$G$2:$G$81,$O15)&"") | I15: =IF($O15="","",INDEX(Papers!$I$2:$I$81,$O15)) | J15: =IF($O15="","",INDEX(Papers!$J$2:$J$81,$O15)&"") -> Philosophy of Management | O15: =IFERROR(MATCH(5,Papers!$O$2:$O$81,0),"") -> 12
B16: =IF($O16="","",INDEX(Papers!$A$2:$A$81,$O16)&"") -> Organizational Silence (lit review) | E16: =IF($O16="","",INDEX(Papers!$F$2:$F$81,$O16)&"") -> Not yet submitted | F16: =IF($O16="","",INDEX(Papers!$G$2:$G$81,$O16)&"") | I16: =IF($O16="","",INDEX(Papers!$I$2:$I$81,$O16)) | J16: =IF($O16="","",INDEX(Papers!$J$2:$J$81,$O16)&"") -> Journal of Information, Communication and Ethics in Society | O16: =IFERROR(MATCH(6,Papers!$O$2:$O$81,0),"") -> 13
B17: =IF($O17="","",INDEX(Papers!$A$2:$A$81,$O17)&"") | E17: =IF($O17="","",INDEX(Papers!$F$2:$F$81,$O17)&"") | F17: =IF($O17="","",INDEX(Papers!$G$2:$G$81,$O17)&"") | I17: =IF($O17="","",INDEX(Papers!$I$2:$I$81,$O17)) | J17: =IF($O17="","",INDEX(Papers!$J$2:$J$81,$O17)&"") | O17: =IFERROR(MATCH(7,Papers!$O$2:$O$81,0),"")
B18: =IF($O18="","",INDEX(Papers!$A$2:$A$81,$O18)&"") | E18: =IF($O18="","",INDEX(Papers!$F$2:$F$81,$O18)&"") | F18: =IF($O18="","",INDEX(Papers!$G$2:$G$81,$O18)&"") | I18: =IF($O18="","",INDEX(Papers!$I$2:$I$81,$O18)) | J18: =IF($O18="","",INDEX(Papers!$J$2:$J$81,$O18)&"") | O18: =IFERROR(MATCH(8,Papers!$O$2:$O$81,0),"")
B19: =IF($O19="","",INDEX(Papers!$A$2:$A$81,$O19)&"") | E19: =IF($O19="","",INDEX(Papers!$F$2:$F$81,$O19)&"") | F19: =IF($O19="","",INDEX(Papers!$G$2:$G$81,$O19)&"") | I19: =IF($O19="","",INDEX(Papers!$I$2:$I$81,$O19)) | J19: =IF($O19="","",INDEX(Papers!$J$2:$J$81,$O19)&"") | O19: =IFERROR(MATCH(9,Papers!$O$2:$O$81,0),"")
B20: =IF($O20="","",INDEX(Papers!$A$2:$A$81,$O20)&"") | E20: =IF($O20="","",INDEX(Papers!$F$2:$F$81,$O20)&"") | F20: =IF($O20="","",INDEX(Papers!$G$2:$G$81,$O20)&"") | I20: =IF($O20="","",INDEX(Papers!$I$2:$I$81,$O20)) | J20: =IF($O20="","",INDEX(Papers!$J$2:$J$81,$O20)&"") | O20: =IFERROR(MATCH(10,Papers!$O$2:$O$81,0),"")
B21: =IF($O21="","",INDEX(Papers!$A$2:$A$81,$O21)&"") | E21: =IF($O21="","",INDEX(Papers!$F$2:$F$81,$O21)&"") | F21: =IF($O21="","",INDEX(Papers!$G$2:$G$81,$O21)&"") | I21: =IF($O21="","",INDEX(Papers!$I$2:$I$81,$O21)) | J21: =IF($O21="","",INDEX(Papers!$J$2:$J$81,$O21)&"") | O21: =IFERROR(MATCH(11,Papers!$O$2:$O$81,0),"")
B22: =IF($O22="","",INDEX(Papers!$A$2:$A$81,$O22)&"") | E22: =IF($O22="","",INDEX(Papers!$F$2:$F$81,$O22)&"") | F22: =IF($O22="","",INDEX(Papers!$G$2:$G$81,$O22)&"") | I22: =IF($O22="","",INDEX(Papers!$I$2:$I$81,$O22)) | J22: =IF($O22="","",INDEX(Papers!$J$2:$J$81,$O22)&"") | O22: =IFERROR(MATCH(12,Papers!$O$2:$O$81,0),"")
B24: Under review now | H24: =IF(COUNT(Submissions!$O$2:$O$1000)>14,"showing longest 14 of "&COUNT(Submissions!$O$2:$O$1000),"longest wait first") -> longest wait first
B25: PAPER | E25: JOURNAL | I25: SUBMITTED | J25: DAYS | K25: CHECK
B26: =IF($O26="","",INDEX(Submissions!$A$2:$A$1000,$O26)&"") -> Death & language: Heidegger–Blanchot | E26: =IF($O26="","",INDEX(Submissions!$B$2:$B$1000,$O26)&"") -> Comparative and Continental Philosophy | I26: =IF($O26="","",INDEX(Submissions!$E$2:$E$1000,$O26)) -> 45812 | J26: =IF($O26="","",INDEX(Submissions!$G$2:$G$1000,$O26)) -> 494 | K26: =IF($O26="","",IF(J26>=2*$M$3,"Overdue: chase editor",IF(J26>=$M$3,"Check status",""))) -> Overdue: chase editor | O26: =IFERROR(MATCH(1,Submissions!$O$2:$O$1000,0),"") -> 7
B27: =IF($O27="","",INDEX(Submissions!$A$2:$A$1000,$O27)&"") -> Farmers’ protest & radical passivity | E27: =IF($O27="","",INDEX(Submissions!$B$2:$B$1000,$O27)&"") -> Applied Linguistics | I27: =IF($O27="","",INDEX(Submissions!$E$2:$E$1000,$O27)) -> 46045 | J27: =IF($O27="","",INDEX(Submissions!$G$2:$G$1000,$O27)) -> 261 | K27: =IF($O27="","",IF(J27>=2*$M$3,"Overdue: chase editor",IF(J27>=$M$3,"Check status",""))) -> Overdue: chase editor | O27: =IFERROR(MATCH(2,Submissions!$O$2:$O$1000,0),"") -> 135
B28: =IF($O28="","",INDEX(Submissions!$A$2:$A$1000,$O28)&"") -> Algorithmic silence & org. power | E28: =IF($O28="","",INDEX(Submissions!$B$2:$B$1000,$O28)&"") -> Organization Theory | I28: =IF($O28="","",INDEX(Submissions!$E$2:$E$1000,$O28)) -> 46153 | J28: =IF($O28="","",INDEX(Submissions!$G$2:$G$1000,$O28)) -> 153 | K28: =IF($O28="","",IF(J28>=2*$M$3,"Overdue: chase editor",IF(J28>=$M$3,"Check status",""))) -> Check status | O28: =IFERROR(MATCH(3,Submissions!$O$2:$O$1000,0),"") -> 78
B29: =IF($O29="","",INDEX(Submissions!$A$2:$A$1000,$O29)&"") -> Intentional tacit knowledge hiding (Malawi) | E29: =IF($O29="","",INDEX(Submissions!$B$2:$B$1000,$O29)&"") -> Global Knowledge, Memory and Communication | I29: =IF($O29="","",INDEX(Submissions!$E$2:$E$1000,$O29)) -> 46232 | J29: =IF($O29="","",INDEX(Submissions!$G$2:$G$1000,$O29)) -> 74 | K29: =IF($O29="","",IF(J29>=2*$M$3,"Overdue: chase editor",IF(J29>=$M$3,"Check status",""))) | O29: =IFERROR(MATCH(4,Submissions!$O$2:$O$1000,0),"") -> 98
B30: =IF($O30="","",INDEX(Submissions!$A$2:$A$1000,$O30)&"") -> Derrida hauntology & memory ethics | E30: =IF($O30="","",INDEX(Submissions!$B$2:$B$1000,$O30)&"") -> Time and Society | I30: =IF($O30="","",INDEX(Submissions!$E$2:$E$1000,$O30)) -> 46289 | J30: =IF($O30="","",INDEX(Submissions!$G$2:$G$1000,$O30)) -> 17 | K30: =IF($O30="","",IF(J30>=2*$M$3,"Overdue: chase editor",IF(J30>=$M$3,"Check status",""))) | O30: =IFERROR(MATCH(5,Submissions!$O$2:$O$1000,0),"") -> 34
B31: =IF($O31="","",INDEX(Submissions!$A$2:$A$1000,$O31)&"") -> ‘One dies’: Blanchot & organizational speech | E31: =IF($O31="","",INDEX(Submissions!$B$2:$B$1000,$O31)&"") -> Organization | I31: =IF($O31="","",INDEX(Submissions!$E$2:$E$1000,$O31)) -> 46296 | J31: =IF($O31="","",INDEX(Submissions!$G$2:$G$1000,$O31)) -> 10 | K31: =IF($O31="","",IF(J31>=2*$M$3,"Overdue: chase editor",IF(J31>=$M$3,"Check status",""))) | O31: =IFERROR(MATCH(6,Submissions!$O$2:$O$1000,0),"") -> 15
B32: =IF($O32="","",INDEX(Submissions!$A$2:$A$1000,$O32)&"") -> Is Leadership Inherently Violent? | E32: =IF($O32="","",INDEX(Submissions!$B$2:$B$1000,$O32)&"") -> Journal of Business Ethics | I32: =IF($O32="","",INDEX(Submissions!$E$2:$E$1000,$O32)) -> 46300 | J32: =IF($O32="","",INDEX(Submissions!$G$2:$G$1000,$O32)) -> 6 | K32: =IF($O32="","",IF(J32>=2*$M$3,"Overdue: chase editor",IF(J32>=$M$3,"Check status",""))) | O32: =IFERROR(MATCH(7,Submissions!$O$2:$O$1000,0),"") -> 160
B33: =IF($O33="","",INDEX(Submissions!$A$2:$A$1000,$O33)&"") -> Cockroaches, Not Citizens (CDA) | E33: =IF($O33="","",INDEX(Submissions!$B$2:$B$1000,$O33)&"") -> Discourse & Communication | I33: =IF($O33="","",INDEX(Submissions!$E$2:$E$1000,$O33)) -> 46300 | J33: =IF($O33="","",INDEX(Submissions!$G$2:$G$1000,$O33)) -> 6 | K33: =IF($O33="","",IF(J33>=2*$M$3,"Overdue: chase editor",IF(J33>=$M$3,"Check status",""))) | O33: =IFERROR(MATCH(8,Submissions!$O$2:$O$1000,0),"") -> 62
B34: =IF($O34="","",INDEX(Submissions!$A$2:$A$1000,$O34)&"") -> Bullshit without a bullshitter (GenAI) | E34: =IF($O34="","",INDEX(Submissions!$B$2:$B$1000,$O34)&"") -> Journal of Management Studies | I34: =IF($O34="","",INDEX(Submissions!$E$2:$E$1000,$O34)) -> 46301 | J34: =IF($O34="","",INDEX(Submissions!$G$2:$G$1000,$O34)) -> 5 | K34: =IF($O34="","",IF(J34>=2*$M$3,"Overdue: chase editor",IF(J34>=$M$3,"Check status",""))) | O34: =IFERROR(MATCH(9,Submissions!$O$2:$O$1000,0),"") -> 68
B35: =IF($O35="","",INDEX(Submissions!$A$2:$A$1000,$O35)&"") -> Cosmoceuticals | E35: =IF($O35="","",INDEX(Submissions!$B$2:$B$1000,$O35)&"") -> IEEE Transactions on Engineering Management | I35: =IF($O35="","",INDEX(Submissions!$E$2:$E$1000,$O35)) -> 46303 | J35: =IF($O35="","",INDEX(Submissions!$G$2:$G$1000,$O35)) -> 3 | K35: =IF($O35="","",IF(J35>=2*$M$3,"Overdue: chase editor",IF(J35>=$M$3,"Check status",""))) | O35: =IFERROR(MATCH(10,Submissions!$O$2:$O$1000,0),"") -> 169
B36: =IF($O36="","",INDEX(Submissions!$A$2:$A$1000,$O36)&"") | E36: =IF($O36="","",INDEX(Submissions!$B$2:$B$1000,$O36)&"") | I36: =IF($O36="","",INDEX(Submissions!$E$2:$E$1000,$O36)) | J36: =IF($O36="","",INDEX(Submissions!$G$2:$G$1000,$O36)) | K36: =IF($O36="","",IF(J36>=2*$M$3,"Overdue: chase editor",IF(J36>=$M$3,"Check status",""))) | O36: =IFERROR(MATCH(11,Submissions!$O$2:$O$1000,0),"")
B37: =IF($O37="","",INDEX(Submissions!$A$2:$A$1000,$O37)&"") | E37: =IF($O37="","",INDEX(Submissions!$B$2:$B$1000,$O37)&"") | I37: =IF($O37="","",INDEX(Submissions!$E$2:$E$1000,$O37)) | J37: =IF($O37="","",INDEX(Submissions!$G$2:$G$1000,$O37)) | K37: =IF($O37="","",IF(J37>=2*$M$3,"Overdue: chase editor",IF(J37>=$M$3,"Check status",""))) | O37: =IFERROR(MATCH(12,Submissions!$O$2:$O$1000,0),"")
B38: =IF($O38="","",INDEX(Submissions!$A$2:$A$1000,$O38)&"") | E38: =IF($O38="","",INDEX(Submissions!$B$2:$B$1000,$O38)&"") | I38: =IF($O38="","",INDEX(Submissions!$E$2:$E$1000,$O38)) | J38: =IF($O38="","",INDEX(Submissions!$G$2:$G$1000,$O38)) | K38: =IF($O38="","",IF(J38>=2*$M$3,"Overdue: chase editor",IF(J38>=$M$3,"Check status",""))) | O38: =IFERROR(MATCH(13,Submissions!$O$2:$O$1000,0),"")
B39: =IF($O39="","",INDEX(Submissions!$A$2:$A$1000,$O39)&"") | E39: =IF($O39="","",INDEX(Submissions!$B$2:$B$1000,$O39)&"") | I39: =IF($O39="","",INDEX(Submissions!$E$2:$E$1000,$O39)) | J39: =IF($O39="","",INDEX(Submissions!$G$2:$G$1000,$O39)) | K39: =IF($O39="","",IF(J39>=2*$M$3,"Overdue: chase editor",IF(J39>=$M$3,"Check status",""))) | O39: =IFERROR(MATCH(14,Submissions!$O$2:$O$1000,0),"")
B41: Pipeline and activity

Sheet How to use
B2: How to use this workbook
B4: The idea | C4: Two sheets hold the data. Everything on the Dashboard is calculated from them. You never edit the Dashboard.
B5: Papers sheet | C5: One row per paper. Short name is the key that links to Submissions, so keep it unique. Stage is calculated. Use ‘Override’ only to mark a paper Closed – rejected (no plan to resubmit), Parked, Withdrawn or Published. Those drop off the ‘Waiting on you’ list.
B6: Submissions sheet | C6: One row per attempt at a journal. Pick the paper, type the journal, set the status and the dates. Add new rows at the bottom, in any order.
B8: When you submit a paper | C8: Add a row (or change a ‘Planned’ row to ‘Under review’): Status = Under review, Date submitted = today.
B9: When a decision arrives | C9: Change Status (Rejected, Revision requested, Accepted…) and fill Date of decision. A rejected paper moves to ‘Needs resubmission’ on the Dashboard straight away.
B10: When you revise and resubmit | C10: Set the old row to ‘Revision resubmitted’ and add a new row for the revised version with Status = Under review.
B11: When you retitle a paper | C11: Update Current title on Papers. Put the old title in the Notes, or in ‘Title used’ on the Submissions row.
B12: Queue of next journals | C12: Add rows with Status = Planned and no dates, in the order you want to try them. The first Planned row shows up as ‘Next in queue’.
B13: A new paper | C13: Add a row on Papers (up to row 81). Then it appears in the Paper dropdown on Submissions.
B15: Stages | C15: Revision due: a journal asked for a revision. Needs resubmission: no journal has it right now. Not yet submitted: never sent out. Under review: with a journal. Accepted.
B16: Days idle | C16: Days since the last decision on a paper that no journal currently holds. Amber at 60+, red at 180+.
B17: Chase editor | C17: Set the number of days in the Dashboard (top right, default 90). Submissions waiting longer are flagged; at twice that they’re marked overdue.
B18: Date cells | C18: Statuses and dates are the only things that matter. Anything with a date but no matching status won’t be counted.

Sheet Papers
A1: Paper (short name, must be unique) | B1: Current title | C1: Authors | D1: Type | E1: Override (optional) | F1: Stage | G1: Last journal tried | H1: Last decision | I1: Days idle | J1: Next journal in queue | K1: Submissions sent | L1: Rejections | M1: Notes | N1: score | O1: rank
A2: Death & language: Heidegger–Blanchot | B2: Death, language, and the limits of communication: Heidegger and Blanchot in dialogue | C2: Kaushal, S., Guha, A. | D2: Journal article | F2: =IF($A2="","",IF($E2<>"",$E2,IF(COUNTIFS(Submissions!$A$2:$A$1000,$A2,Submissions!$D$2:$D$1000,"Accepted")>0,"Accepted",IF(COUNTIFS(Submissions!$A$2:$A$1000,$A2,Submissions!$D$2:$D$1000,"Revision requested")>0,"Revision due",IF(COUNTIFS(Submissions!$A$2:$A$1000,$A2,Submissions!$D$2:$D$1000,"Under review")>0,"Under review",IF($K2>0,"Needs resubmission","Not yet submitted")))))) -> Under review | G2: =IF($A2="","",IFERROR(INDEX(Submissions!$B$2:$B$1000,MATCH(_xlfn.MAXIFS(Submissions!$L$2:$L$1000,Submissions!$A$2:$A$1000,$A2),Submissions!$L$2:$L$1000,0)),"")) -> Comparative and Continental Philosophy | H2: =IF($A2="","",IF(_xlfn.MAXIFS(Submissions!$F$2:$F$1000,Submissions!$A$2:$A$1000,$A2)=0,"",_xlfn.MAXIFS(Submissions!$F$2:$F$1000,Submissions!$A$2:$A$1000,$A2))) -> 45804 | I2: =IF($F2="Needs resubmission",IF($H2="","",TODAY()-$H2),"") | J2: =IF($A2="","",IF(_xlfn.MINIFS(Submissions!$M$2:$M$1000,Submissions!$A$2:$A$1000,$A2)=0,"",INDEX(Submissions!$B$2:$B$1000,_xlfn.MINIFS(Submissions!$M$2:$M$1000,Submissions!$A$2:$A$1000,$A2)-1))) -> Research in Phenomenology | K2: =IF($A2="","",SUMIFS(Submissions!$J$2:$J$1000,Submissions!$A$2:$A$1000,$A2)) -> 7 | L2: =IF($A2="","",COUNTIFS(Submissions!$A$2:$A$1000,$A2,Submissions!$D$2:$D$1000,"Rejected")+COUNTIFS(Submissions!$A$2:$A$1000,$A2,Submissions!$D$2:$D$1000,"Returned by office")) -> 6 | M2: 7k words. Earlier title: The Voice of Silence: Heidegger and Blanchot on Death and the Limits of Communication. Your note: Research in Phenomenology first, then Angelaki, then Continental Philosophy Review. | N2: =IF(IF($F2="Revision due",3000,IF($F2="Needs resubmission",2000,IF($F2="Not yet submitted",1000,"")))="","",IF($F2="Revision due",3000,IF($F2="Needs resubmission",2000,IF($F2="Not yet submitted",1000,"")))+IF($I2="",0,MIN($I2,999))+(1000-ROW())/100000) | O2: =IF($N2="","",RANK($N2,$N$2:$N$81))
A3: ‘One dies’: Blanchot & organizational speech | B3: ‘One dies’: Blanchot, the impossibility of death and the unworking of organizational speech | D3: Journal article | F3: =IF($A3="","",IF($E3<>"",$E3,IF(COUNTIFS(Submissions!$A$2:$A$1000,$A3,Submissions!$D$2:$D$1000,"Accepted")>0,"Accepted",IF(COUNTIFS(Submissions!$A$2:$A$1000,$A3,Submissions!$D$2:$D$1000,"Revision requested")>0,"Revision due",IF(COUNTIFS(Submissions!$A$2:$A$1000,$A3,Submissions!$D$2:$D$1000,"Under review")>0,"Under review",IF($K3>0,"Needs resubmission","Not yet submitted")))))) -> Under review | G3: =IF($A3="","",IFERROR(INDEX(Submissions!$B$2:$B$1000,MATCH(_xlfn.MAXIFS(Submissions!$L$2:$L$1000,Submissions!$A$2:$A$1000,$A3),Submissions!$L$2:$L$1000,0)),"")) -> Organization | H3: =IF($A3="","",IF(_xlfn.MAXIFS(Submissions!$F$2:$F$1000,Submissions!$A$2:$A$1000,$A3)=0,"",_xlfn.MAXIFS(Submissions!$F$2:$F$1000,Submissions!$A$2:$A$1000,$A3))) | I3: =IF($F3="Needs resubmission",IF($H3="","",TODAY()-$H3),"") | J3: =IF($A3="","",IF(_xlfn.MINIFS(Submissions!$M$2:$M$1000,Submissions!$A$2:$A$1000,$A3)=0,"",INDEX(Submissions!$B$2:$B$1000,_xlfn.MINIFS(Submissions!$M$2:$M$1000,Submissions!$A$2:$A$1000,$A3)-1))) -> Human Relations | K3: =IF($A3="","",SUMIFS(Submissions!$J$2:$J$1000,Submissions!$A$2:$A$1000,$A3)) -> 1 | L3: =IF($A3="","",COUNTIFS(Submissions!$A$2:$A$1000,$A3,Submissions!$D$2:$D$1000,"Rejected")+COUNTIFS(Submissions!$A$2:$A$1000,$A3,Submissions!$D$2:$D$1000,"Returned by office")) -> 0 | N3: =IF(IF($F3="Revision due",3000,IF($F3="Needs resubmission",2000,IF($F3="Not yet submitted",1000,"")))="","",IF($F3="Revision due",3000,IF($F3="Needs resubmission",2000,IF($F3="Not yet submitted",1000,"")))+IF($I3="",0,MIN($I3,999))+(1000-ROW())/100000) | O3: =IF($N3="","",RANK($N3,$N$2:$N$81))
A4: Derrida hauntology & memory ethics | B4: The Time That Obligates: Derrida, Levinas, and a Hauntological Ethics of Memory | C4: Kaushal, S., Guha, A. | D4: Journal article | F4: =IF($A4="","",IF($E4<>"",$E4,IF(COUNTIFS(Submissions!$A$2:$A$1000,$A4,Submissions!$D$2:$D$1000,"Accepted")>0,"Accepted",IF(COUNTIFS(Submissions!$A$2:$A$1000,$A4,Submissions!$D$2:$D$1000,"Revision requested")>0,"Revision due",IF(COUNTIFS(Submissions!$A$2:$A$1000,$A4,Submissions!$D$2:$D$1000,"Under review")>0,"Under review",IF($K4>0,"Needs resubmission","Not yet submitted")))))) -> Under review | G4: =IF($A4="","",IFERROR(INDEX(Submissions!$B$2:$B$1000,MATCH(_xlfn.MAXIFS(Submissions!$L$2:$L$1000,Submissions!$A$2:$A$1000,$A4),Submissions!$L$2:$L$1000,0)),"")) -> Time and Society | H4: =IF($A4="","",IF(_xlfn.MAXIFS(Submissions!$F$2:$F$1000,Submissions!$A$2:$A$1000,$A4)=0,"",_xlfn.MAXIFS(Submissions!$F$2:$F$1000,Submissions!$A$2:$A$1000,$A4))) -> 45867 | I4: =IF($F4="Needs resubmission",IF($H4="","",TODAY()-$H4),"") | J4: =IF($A4="","",IF(_xlfn.MINIFS(Submissions!$M$2:$M$1000,Submissions!$A$2:$A$1000,$A4)=0,"",INDEX(Submissions!$B$2:$B$1000,_xlfn.MINIFS(Submissions!$M$2:$M$1000,Submissions!$A$2:$A$1000,$A4)-1))) -> Sociological Inquiry (Wiley) | K4: =IF($A4="","",SUMIFS(Submissions!$J$2:$J$1000,Submissions!$A$2:$A$1000,$A4)) -> 17 | L4: =IF($A4="","",COUNTIFS(Submissions!$A$2:$A$1000,$A4,Submissions!$D$2:$D$1000,"Rejected")+COUNTIFS(Submissions!$A$2:$A$1000,$A4,Submissions!$D$2:$D$1000,"Returned by office")) -> 16 | M4: Earlier titles: The Specter of Time: Tracing Derrida’s Hauntology… | The Ghosts of Time – Derrida’s Spectral Logic and the Haunting of Historical Presence | Spectral memory, différance, and the ethics of unfinished histories | Derrida, Hauntology, and the Temporal Ethics of Memory | N4: =IF(IF($F4="Revision due",3000,IF($F4="Needs resubmission",2000,IF($F4="Not yet submitted",1000,"")))="","",IF($F4="Revision due",3000,IF($F4="Needs resubmission",2000,IF($F4="Not yet submitted",1000,"")))+IF($I4="",0,MIN($I4,999))+(1000-ROW())/100000) | O4: =IF($N4="","",RANK($N4,$N$2:$N$81))
A5: Cockroach Spoke Back (Instagram, irony) | B5: When the Cockroach Spoke Back: Satirical Citizenship, Irony, and the Limits of Platform Politics | C5: Kaushal, S., Guha, A. | D5: Journal article | F5: =IF($A5="","",IF($E5<>"",$E5,IF(COUNTIFS(Submissions!$A$2:$A$1000,$A5,Submissions!$D$2:$D$1000,"Accepted")>0,"Accepted",IF(COUNTIFS(Submissions!$A$2:$A$1000,$A5,Submissions!$D$2:$D$1000,"Revision requested")>0,"Revision due",IF(COUNTIFS(Submissions!$A$2:$A$1000,$A5,Submissions!$D$2:$D$1000,"Under review")>0,"Under review",IF($K5>0,"Needs resubmission","Not yet submitted")))))) -> Needs resubmission | G5: =IF($A5="","",IFERROR(INDEX(Submissions!$B$2:$B$1000,MATCH(_xlfn.MAXIFS(Submissions!$L$2:$L$1000,Submissions!$A$2:$A$1000,$A5),Submissions!$L$2:$L$1000,0)),"")) -> Media, Culture & Society | H5: =IF($A5="","",IF(_xlfn.MAXIFS(Submissions!$F$2:$F$1000,Submissions!$A$2:$A$1000,$A5)=0,"",_xlfn.MAXIFS(Submissions!$F$2:$F$1000,Submissions!$A$2:$A$1000,$A5))) -> 46204 | I5: =IF($F5="Needs resubmission",IF($H5="","",TODAY()-$H5),"") -> 102 | J5: =IF($A5="","",IF(_xlfn.MINIFS(Submissions!$M$2:$M$1000,Submissions!$A$2:$A$1000,$A5)=0,"",INDEX(Submissions!$B$2:$B$1000,_xlfn.MINIFS(Submissions!$M$2:$M$1000,Submissions!$A$2:$A$1000,$A5)-1))) | K5: =IF($A5="","",SUMIFS(Submissions!$J$2:$J$1000,Submissions!$A$2:$A$1000,$A5)) -> 2 | L5: =IF($A5="","",COUNTIFS(Submissions!$A$2:$A$1000,$A5,Submissions!$D$2:$D$1000,"Rejected")+COUNTIFS(Submissions!$A$2:$A$1000,$A5,Submissions!$D$2:$D$1000,"Returned by office")) -> 2 | N5: =IF(IF($F5="Revision due",3000,IF($F5="Needs resubmission",2000,IF($F5="Not yet submitted",1000,"")))="","",IF($F5="Revision due",3000,IF($F5="Needs resubmission",2000,IF($F5="Not yet submitted",1000,"")))+IF($I5="",0,MIN($I5,999))+(1000-ROW())/100000) -> 2102.01 | O5: =IF($N5="","",RANK($N5,$N$2:$N$81)) -> 2
A6: Cockroaches, Not Citizens (CDA) | B6: Cockroaches, Not Citizens: A Critical-Generational-Socio-Cognitive Discourse Analysis of Delegitimization of India’s Cockroach Janta Party | D6: Journal article | F6: =IF($A6="","",IF($E6<>"",$E6,IF(COUNTIFS(Submissions!$A$2:$A$1000,$A6,Submissions!$D$2:$D$1000,"Accepted")>0,"Accepted",IF(COUNTIFS(Submissions!$A$2:$A$1000,$A6,Submissions!$D$2:$D$1000,"Revision requested")>0,"Revision due",IF(COUNTIFS(Submissions!$A$2:$A$1000,$A6,Submissions!$D$2:$D$1000,"Under review")>0,"Under review",IF($K6>0,"Needs resubmission","Not yet submitted")))))) -> Under review | G6: =IF($A6="","",IFERROR(INDEX(Submissions!$B$2:$B$1000,MATCH(_xlfn.MAXIFS(Submissions!$L$2:$L$1000,Submissions!$A$2:$A$1000,$A6),Submissions!$L$2:$L$1000,0)),"")) -> Discourse & Communication | H6: =IF($A6="","",IF(_xlfn.MAXIFS(Submissions!$F$2:$F$1000,Submissions!$A$2:$A$1000,$A6)=0,"",_xlfn.MAXIFS(Submissions!$F$2:$F$1000,Submissions!$A$2:$A$1000,$A6))) -> 46299 | I6: =IF($F6="Needs resubmission",IF($H6="","",TODAY()-$H6),"") | J6: =IF($A6="","",IF(_xlfn.MINIFS(Submissions!$M$2:$M$1000,Submissions!$A$2:$A$1000,$A6)=0,"",INDEX(Submissions!$B$2:$B$1000,_xlfn.MINIFS(Submissions!$M$2:$M$1000,Submissions!$A$2:$A$1000,$A6)-1))) -> Alternatives: Global, Local, Political | K6: =IF($A6="","",SUMIFS(Submissions!$J$2:$J$1000,Submissions!$A$2:$A$1000,$A6)) -> 3 | L6: =IF($A6="","",COUNTIFS(Submissions!$A$2:$A$1000,$A6,Submissions!$D$2:$D$1000,"Rejected")+COUNTIFS(Submissions!$A$2:$A$1000,$A6,Submissions!$D$2:$D$1000,"Returned by office")) -> 2 | N6: =IF(IF($F6="Revision due",3000,IF($F6="Needs resubmission",2000,IF($F6="Not yet submitted",1000,"")))="","",IF($F6="Revision due",3000,IF($F6="Needs resubmission",2000,IF($F6="Not yet submitted",1000,"")))+IF($I6="",0,MIN($I6,999))+(1000-ROW())/100000) | O6: =IF($N6="","",RANK($N6,$N$2:$N$81))
A7: Distributed securitization (India SIR) | B7: Distributed securitization: threat and procedure in India’s Special Intensive Revision of electoral rolls | D7: Journal article | F7: =IF($A7="","",IF($E7<>"",$E7,IF(COUNTIFS(Submissions!$A$2:$A$1000,$A7,Submissions!$D$2:$D$1000,"Accepted")>0,"Accepted",IF(COUNTIFS(Submissions!$A$2:$A$1000,$A7,Submissions!$D$2:$D$1000,"Revision requested")>0,"Revision due",IF(COUNTIFS(Submissions!$A$2:$A$1000,$A7,Submissions!$D$2:$D$1000,"Under review")>0,"Under review",IF($K7>0,"Needs resubmission","Not yet submitted")))))) -> Not yet submitted | G7: =IF($A7="","",IFERROR(INDEX(Submissions!$B$2:$B$1000,MATCH(_xlfn.MAXIFS(Submissions!$L$2:$L$1000,Submissions!$A$2:$A$1000,$A7),Submissions!$L$2:$L$1000,0)),"")) | H7: =IF($A7="","",IF(_xlfn.MAXIFS(Submissions!$F$2:$F$1000,Submissions!$A$2:$A$1000,$A7)=0,"",_xlfn.MAXIFS(Submissions!$F$2:$F$1000,Submissions!$A$2:$A$1000,$A7))) | I7: =IF($F7="Needs resubmission",IF($H7="","",TODAY()-$H7),"") | J7: =IF($A7="","",IF(_xlfn.MINIFS(Submissions!$M$2:$M$1000,Submissions!$A$2:$A$1000,$A7)=0,"",INDEX(Submissions!$B$2:$B$1000,_xlfn.MINIFS(Submissions!$M$2:$M$1000,Submissions!$A$2:$A$1000,$A7)-1))) -> Security Studies | K7: =IF($A7="","",SUMIFS(Submissions!$J$2:$J$1000,Submissions!$A$2:$A$1000,$A7)) -> 0 | L7: =IF($A7="","",COUNTIFS(Submissions!$A$2:$A$1000,$A7,Submissions!$D$2:$D$1000,"Rejected")+COUNTIFS(Submissions!$A$2:$A$1000,$A7,Submissions!$D$2:$D$1000,"Returned by office")) -> 0 | N7: =IF(IF($F7="Revision due",3000,IF($F7="Needs resubmission",2000,IF($F7="Not yet submitted",1000,"")))="","",IF($F7="Revision due",3000,IF($F7="Needs resubmission",2000,IF($F7="Not yet submitted",1000,"")))+IF($I7="",0,MIN($I7,999))+(1000-ROW())/100000) -> 1000.0099 | O7: =IF($N7="","",RANK($N7,$N$2:$N$81)) -> 4
A8: Bullshit without a bullshitter (GenAI) | B8: Bullshit Without a Bullshitter: Generative AI, Uptake, and the Organizational Laundering of Indifference to Truth | D8: Journal article | F8: =IF($A8="","",IF($E8<>"",$E8,IF(COUNTIFS(Submissions!$A$2:$A$1000,$A8,Submissions!$D$2:$D$1000,"Accepted")>0,"Accepted",IF(COUNTIFS(Submissions!$A$2:$A$1000,$A8,Submissions!$D$2:$D$1000,"Revision requested")>0,"Revision due",IF(COUNTIFS(Submissions!$A$2:$A$1000,$A8,Submissions!$D$2:$D$1000,"Under review")>0,"Under review",IF($K8>0,"Needs resubmission","Not yet submitted")))))) -> Under review | G8: =IF($A8="","",IFERROR(INDEX(Submissions!$B$2:$B$1000,MATCH(_xlfn.MAXIFS(Submissions!$L$2:$L$1000,Submissions!$A$2:$A$1000,$A8),Submissions!$L$2:$L$1000,0)),"")) -> Journal of Management Studies | H8: =IF($A8="","",IF(_xlfn.MAXIFS(Submissions!$F$2:$F$1000,Submissions!$A$2:$A$1000,$A8)=0,"",_xlfn.MAXIFS(Submissions!$F$2:$F$1000,Submissions!$A$2:$A$1000,$A8))) -> 46301 | I8: =IF($F8="Needs resubmission",IF($H8="","",TODAY()-$H8),"") | J8: =IF($A8="","",IF(_xlfn.MINIFS(Submissions!$M$2:$M$1000,Submissions!$A$2:$A$1000,$A8)=0,"",INDEX(Submissions!$B$2:$B$1000,_xlfn.MINIFS(Submissions!$M$2:$M$1000,Submissions!$A$2:$A$1000,$A8)-1))) -> Human Relations | K8: =IF($A8="","",SUMIFS(Submissions!$J$2:$J$1000,Submissions!$A$2:$A$1000,$A8)) -> 2 | L8: =IF($A8="","",COUNTIFS(Submissions!$A$2:$A$1000,$A8,Submissions!$D$2:$D$1000,"Rejected")+COUNTIFS(Submissions!$A$2:$A$1000,$A8,Submissions!$D$2:$D$1000,"Returned by office")) -> 1 | N8: =IF(IF($F8="Revision due",3000,IF($F8="Needs resubmission",2000,IF($F8="Not yet submitted",1000,"")))="","",IF($F8="Revision due",3000,IF($F8="Needs resubmission",2000,IF($F8="Not yet submitted",1000,"")))+IF($I8="",0,MIN($I8,999))+(1000-ROW())/100000) | O8: =IF($N8="","",RANK($N8,$N$2:$N$81))
A9: From Devta to Musafir (EPW) | B9: From Devta to Musafir | D9: EPW / short piece | E9: Closed – rejected | F9: =IF($A9="","",IF($E9<>"",$E9,IF(COUNTIFS(Submissions!$A$2:$A$1000,$A9,Submissions!$D$2:$D$1000,"Accepted")>0,"Accepted",IF(COUNTIFS(Submissions!$A$2:$A$1000,$A9,Submissions!$D$2:$D$1000,"Revision requested")>0,"Revision due",IF(COUNTIFS(Submissions!$A$2:$A$1000,$A9,Submissions!$D$2:$D$1000,"Under review")>0,"Under review",IF($K9>0,"Needs resubmission","Not yet submitted")))))) -> Closed – rejected | G9: =IF($A9="","",IFERROR(INDEX(Submissions!$B$2:$B$1000,MATCH(_xlfn.MAXIFS(Submissions!$L$2:$L$1000,Submissions!$A$2:$A$1000,$A9),Submissions!$L$2:$L$1000,0)),"")) -> EPW: Postscript | H9: =IF($A9="","",IF(_xlfn.MAXIFS(Submissions!$F$2:$F$1000,Submissions!$A$2:$A$1000,$A9)=0,"",_xlfn.MAXIFS(Submissions!$F$2:$F$1000,Submissions!$A$2:$A$1000,$A9))) -> 46298 | I9: =IF($F9="Needs resubmission",IF($H9="","",TODAY()-$H9),"") | J9: =IF($A9="","",IF(_xlfn.MINIFS(Submissions!$M$2:$M$1000,Submissions!$A$2:$A$1000,$A9)=0,"",INDEX(Submissions!$B$2:$B$1000,_xlfn.MINIFS(Submissions!$M$2:$M$1000,Submissions!$A$2:$A$1000,$A9)-1))) | K9: =IF($A9="","",SUMIFS(Submissions!$J$2:$J$1000,Submissions!$A$2:$A$1000,$A9)) -> 1 | L9: =IF($A9="","",COUNTIFS(Submissions!$A$2:$A$1000,$A9,Submissions!$D$2:$D$1000,"Rejected")+COUNTIFS(Submissions!$A$2:$A$1000,$A9,Submissions!$D$2:$D$1000,"Returned by office")) -> 1 | N9: =IF(IF($F9="Revision due",3000,IF($F9="Needs resubmission",2000,IF($F9="Not yet submitted",1000,"")))="","",IF($F9="Revision due",3000,IF($F9="Needs resubmission",2000,IF($F9="Not yet submitted",1000,"")))+IF($I9="",0,MIN($I9,999))+(1000-ROW())/100000) | O9: =IF($N9="","",RANK($N9,$N$2:$N$81))
A10: Algorithmic silence & org. power | B10: Algorithmic silence and organizational power: digital erasure and the politics of absence | C10: Kaushal, S., Guha, A. | D10: Journal article | F10: =IF($A10="","",IF($E10<>"",$E10,IF(COUNTIFS(Submissions!$A$2:$A$1000,$A10,Submissions!$D$2:$D$1000,"Accepted")>0,"Accepted",IF(COUNTIFS(Submissions!$A$2:$A$1000,$A10,Submissions!$D$2:$D$1000,"Revision requested")>0,"Revision due",IF(COUNTIFS(Submissions!$A$2:$A$1000,$A10,Submissions!$D$2:$D$1000,"Under review")>0,"Under review",IF($K10>0,"Needs resubmission","Not yet submitted")))))) -> Under review | G10: =IF($A10="","",IFERROR(INDEX(Submissions!$B$2:$B$1000,MATCH(_xlfn.MAXIFS(Submissions!$L$2:$L$1000,Submissions!$A$2:$A$1000,$A10),Submissions!$L$2:$L$1000,0)),"")) -> Organization Theory | H10: =IF($A10="","",IF(_xlfn.MAXIFS(Submissions!$F$2:$F$1000,Submissions!$A$2:$A$1000,$A10)=0,"",_xlfn.MAXIFS(Submissions!$F$2:$F$1000,Submissions!$A$2:$A$1000,$A10))) -> 46132 | I10: =IF($F10="Needs resubmission",IF($H10="","",TODAY()-$H10),"") | J10: =IF($A10="","",IF(_xlfn.MINIFS(Submissions!$M$2:$M$1000,Submissions!$A$2:$A$1000,$A10)=0,"",INDEX(Submissions!$B$2:$B$1000,_xlfn.MINIFS(Submissions!$M$2:$M$1000,Submissions!$A$2:$A$1000,$A10)-1))) -> Media, Culture & Society | K10: =IF($A10="","",SUMIFS(Submissions!$J$2:$J$1000,Submissions!$A$2:$A$1000,$A10)) -> 8 | L10: =IF($A10="","",COUNTIFS(Submissions!$A$2:$A$1000,$A10,Submissions!$D$2:$D$1000,"Rejected")+COUNTIFS(Submissions!$A$2:$A$1000,$A10,Submissions!$D$2:$D$1000,"Returned by office")) -> 7 | M10: Earlier title: The algorithmic vernacular: how AI co-authors organizational language (assumed same paper; split it if not). | N10: =IF(IF($F10="Revision due",3000,IF($F10="Needs resubmission",2000,IF($F10="Not yet submitted",1000,"")))="","",IF($F10="Revision due",3000,IF($F10="Needs resubmission",2000,IF($F10="Not yet submitted",1000,"")))+IF($I10="",0,MIN($I10,999))+(1000-ROW())/100000) | O10: =IF($N10="","",RANK($N10,$N$2:$N$81))
A11: Intentional tacit knowledge hiding (Malawi) | B11: Intentional Tacit Knowledge Hiding in Public Service: Evidence from Former Principal Secretaries in Malawi | C11: Nyoni, A.M., Kaushal, S., Kovid, R.K., Guha, A. | D11: Journal article | F11: =IF($A11="","",IF($E11<>"",$E11,IF(COUNTIFS(Submissions!$A$2:$A$1000,$A11,Submissions!$D$2:$D$1000,"Accepted")>0,"Accepted",IF(COUNTIFS(Submissions!$A$2:$A$1000,$A11,Submissions!$D$2:$D$1000,"Revision requested")>0,"Revision due",IF(COUNTIFS(Submissions!$A$2:$A$1000,$A11,Submissions!$D$2:$D$1000,"Under review")>0,"Under review",IF($K11>0,"Needs resubmission","Not yet submitted")))))) -> Under review | G11: =IF($A11="","",IFERROR(INDEX(Submissions!$B$2:$B$1000,MATCH(_xlfn.MAXIFS(Submissions!$L$2:$L$1000,Submissions!$A$2:$A$1000,$A11),Submissions!$L$2:$L$1000,0)),"")) -> Global Knowledge, Memory and Communication | H11: =IF($A11="","",IF(_xlfn.MAXIFS(Submissions!$F$2:$F$1000,Submissions!$A$2:$A$1000,$A11)=0,"",_xlfn.MAXIFS(Submissions!$F$2:$F$1000,Submissions!$A$2:$A$1000,$A11))) -> 46229 | I11: =IF($F11="Needs resubmission",IF($H11="","",TODAY()-$H11),"") | J11: =IF($A11="","",IF(_xlfn.MINIFS(Submissions!$M$2:$M$1000,Submissions!$A$2:$A$1000,$A11)=0,"",INDEX(Submissions!$B$2:$B$1000,_xlfn.MINIFS(Submissions!$M$2:$M$1000,Submissions!$A$2:$A$1000,$A11)-1))) -> Group & Organization Management | K11: =IF($A11="","",SUMIFS(Submissions!$J$2:$J$1000,Submissions!$A$2:$A$1000,$A11)) -> 11 | L11: =IF($A11="","",COUNTIFS(Submissions!$A$2:$A$1000,$A11,Submissions!$D$2:$D$1000,"Rejected")+COUNTIFS(Submissions!$A$2:$A$1000,$A11,Submissions!$D$2:$D$1000,"Returned by office")) -> 10 | M11: Other titles used: …in Public Sector Leadership: Risks for Governance and Succession | …and its Implications: Evidence from Public Sector Leadership | N11: =IF(IF($F11="Revision due",3000,IF($F11="Needs resubmission",2000,IF($F11="Not yet submitted",1000,"")))="","",IF($F11="Revision due",3000,IF($F11="Needs resubmission",2000,IF($F11="Not yet submitted",1000,"")))+IF($I11="",0,MIN($I11,999))+(1000-ROW())/100000) | O11: =IF($N11="","",RANK($N11,$N$2:$N$81))
A12: From Medium to Interlocutor (GenAI) | B12: From Medium to Interlocutor: Reconfiguring Communication, Agency, and Power in the Age of Generative AI | C12: Guha, A., Kaushal, S. | D12: Journal article | F12: =IF($A12="","",IF($E12<>"",$E12,IF(COUNTIFS(Submissions!$A$2:$A$1000,$A12,Submissions!$D$2:$D$1000,"Accepted")>0,"Accepted",IF(COUNTIFS(Submissions!$A$2:$A$1000,$A12,Submissions!$D$2:$D$1000,"Revision requested")>0,"Revision due",IF(COUNTIFS(Submissions!$A$2:$A$1000,$A12,Submissions!$D$2:$D$1000,"Under review")>0,"Under review",IF($K12>0,"Needs resubmission","Not yet submitted")))))) -> Needs resubmission | G12: =IF($A12="","",IFERROR(INDEX(Submissions!$B$2:$B$1000,MATCH(_xlfn.MAXIFS(Submissions!$L$2:$L$1000,Submissions!$A$2:$A$1000,$A12),Submissions!$L$2:$L$1000,0)),"")) -> Information, Communication & Society | H12: =IF($A12="","",IF(_xlfn.MAXIFS(Submissions!$F$2:$F$1000,Submissions!$A$2:$A$1000,$A12)=0,"",_xlfn.MAXIFS(Submissions!$F$2:$F$1000,Submissions!$A$2:$A$1000,$A12))) -> 46305 | I12: =IF($F12="Needs resubmission",IF($H12="","",TODAY()-$H12),"") -> 1 | J12: =IF($A12="","",IF(_xlfn.MINIFS(Submissions!$M$2:$M$1000,Submissions!$A$2:$A$1000,$A12)=0,"",INDEX(Submissions!$B$2:$B$1000,_xlfn.MINIFS(Submissions!$M$2:$M$1000,Submissions!$A$2:$A$1000,$A12)-1))) -> Journal of Computer-Mediated Communication | K12: =IF($A12="","",SUMIFS(Submissions!$J$2:$J$1000,Submissions!$A$2:$A$1000,$A12)) -> 5 | L12: =IF($A12="","",COUNTIFS(Submissions!$A$2:$A$1000,$A12,Submissions!$D$2:$D$1000,"Rejected")+COUNTIFS(Submissions!$A$2:$A$1000,$A12,Submissions!$D$2:$D$1000,"Returned by office")) -> 5 | M12: Earlier title: The Algorithmic Interlocutor: Reconceptualizing AI as a Communicative Actor in Human Interaction | N12: =IF(IF($F12="Revision due",3000,IF($F12="Needs resubmission",2000,IF($F12="Not yet submitted",1000,"")))="","",IF($F12="Revision due",3000,IF($F12="Needs resubmission",2000,IF($F12="Not yet submitted",1000,"")))+IF($I12="",0,MIN($I12,999))+(1000-ROW())/100000) -> 2001.0099 | O12: =IF($N12="","",RANK($N12,$N$2:$N$81)) -> 3
A13: Right to the Secret (Blanchot–Heidegger) | B13: Right to the Secret (Blanchot, Heidegger) | D13: Journal article | F13: =IF($A13="","",IF($E13<>"",$E13,IF(COUNTIFS(Submissions!$A$2:$A$1000,$A13,Submissions!$D$2:$D$1000,"Accepted")>0,"Accepted",IF(COUNTIFS(Submissions!$A$2:$A$1000,$A13,Submissions!$D$2:$D$1000,"Revision requested")>0,"Revision due",IF(COUNTIFS(Submissions!$A$2:$A$1000,$A13,Submissions!$D$2:$D$1000,"Under review")>0,"Under review",IF($K13>0,"Needs resubmission","Not yet submitted")))))) -> Not yet submitted | G13: =IF($A13="","",IFERROR(INDEX(Submissions!$B$2:$B$1000,MATCH(_xlfn.MAXIFS(Submissions!$L$2:$L$1000,Submissions!$A$2:$A$1000,$A13),Submissions!$L$2:$L$1000,0)),"")) | H13: =IF($A13="","",IF(_xlfn.MAXIFS(Submissions!$F$2:$F$1000,Submissions!$A$2:$A$1000,$A13)=0,"",_xlfn.MAXIFS(Submissions!$F$2:$F$1000,Submissions!$A$2:$A$1000,$A13))) | I13: =IF($F13="Needs resubmission",IF($H13="","",TODAY()-$H13),"") | J13: =IF($A13="","",IF(_xlfn.MINIFS(Submissions!$M$2:$M$1000,Submissions!$A$2:$A$1000,$A13)=0,"",INDEX(Submissions!$B$2:$B$1000,_xlfn.MINIFS(Submissions!$M$2:$M$1000,Submissions!$A$2:$A$1000,$A13)-1))) -> Philosophy of Management | K13: =IF($A13="","",SUMIFS(Submissions!$J$2:$J$1000,Submissions!$A$2:$A$1000,$A13)) -> 0 | L13: =IF($A13="","",COUNTIFS(Submissions!$A$2:$A$1000,$A13,Submissions!$D$2:$D$1000,"Rejected")+COUNTIFS(Submissions!$A$2:$A$1000,$A13,Submissions!$D$2:$D$1000,"Returned by office")) -> 0 | N13: =IF(IF($F13="Revision due",3000,IF($F13="Needs resubmission",2000,IF($F13="Not yet submitted",1000,"")))="","",IF($F13="Revision due",3000,IF($F13="Needs resubmission",2000,IF($F13="Not yet submitted",1000,"")))+IF($I13="",0,MIN($I13,999))+(1000-ROW())/100000) -> 1000.0099 | O13: =IF($N13="","",RANK($N13,$N$2:$N$81)) -> 5
A14: Organizational Silence (lit review) | B14: Organizational Silence (literature review) | D14: Journal article | F14: =IF($A14="","",IF($E14<>"",$E14,IF(COUNTIFS(Submissions!$A$2:$A$1000,$A14,Submissions!$D$2:$D$1000,"Accepted")>0,"Accepted",IF(COUNTIFS(Submissions!$A$2:$A$1000,$A14,Submissions!$D$2:$D$1000,"Revision requested")>0,"Revision due",IF(COUNTIFS(Submissions!$A$2:$A$1000,$A14,Submissions!$D$2:$D$1000,"Under review")>0,"Under review",IF($K14>0,"Needs resubmission","Not yet submitted")))))) -> Not yet submitted | G14: =IF($A14="","",IFERROR(INDEX(Submissions!$B$2:$B$1000,MATCH(_xlfn.MAXIFS(Submissions!$L$2:$L$1000,Submissions!$A$2:$A$1000,$A14),Submissions!$L$2:$L$1000,0)),"")) | H14: =IF($A14="","",IF(_xlfn.MAXIFS(Submissions!$F$2:$F$1000,Submissions!$A$2:$A$1000,$A14)=0,"",_xlfn.MAXIFS(Submissions!$F$2:$F$1000,Submissions!$A$2:$A$1000,$A14))) | I14: =IF($F14="Needs resubmission",IF($H14="","",TODAY()-$H14),"") | J14: =IF($A14="","",IF(_xlfn.MINIFS(Submissions!$M$2:$M$1000,Submissions!$A$2:$A$1000,$A14)=0,"",INDEX(Submissions!$B$2:$B$1000,_xlfn.MINIFS(Submissions!$M$2:$M$1000,Submissions!$A$2:$A$1000,$A14)-1))) -> Journal of Information, Communication and Ethics in Society | K14: =IF($A14="","",SUMIFS(Submissions!$J$2:$J$1000,Submissions!$A$2:$A$1000,$A14)) -> 0 | L14: =IF($A14="","",COUNTIFS(Submissions!$A$2:$A$1000,$A14,Submissions!$D$2:$D$1000,"Rejected")+COUNTIFS(Submissions!$A$2:$A$1000,$A14,Submissions!$D$2:$D$1000,"Returned by office")) -> 0 | M14: Old sheet numbered this list 1–4 and 7–10 (5 and 6 were missing). | N14: =IF(IF($F14="Revision due",3000,IF($F14="Needs resubmission",2000,IF($F14="Not yet submitted",1000,"")))="","",IF($F14="Revision due",3000,IF($F14="Needs resubmission",2000,IF($F14="Not yet submitted",1000,"")))+IF($I14="",0,MIN($I14,999))+(1000-ROW())/100000) -> 1000.0099 | O14: =IF($N14="","",RANK($N14,$N$2:$N$81)) -> 6
A15: Farmers’ protest & radical passivity | B15: Toward a Constructive Protest Communication Framework: Radical Passivity and Ethical Address in the 2020–2021 Indian Farmers’ Protest | C15: Kaushal, S., Guha, A. | D15: Journal article | F15: =IF($A15="","",IF($E15<>"",$E15,IF(COUNTIFS(Submissions!$A$2:$A$1000,$A15,Submissions!$D$2:$D$1000,"Accepted")>0,"Accepted",IF(COUNTIFS(Submissions!$A$2:$A$1000,$A15,Submissions!$D$2:$D$1000,"Revision requested")>0,"Revision due",IF(COUNTIFS(Submissions!$A$2:$A$1000,$A15,Submissions!$D$2:$D$1000,"Under review")>0,"Under review",IF($K15>0,"Needs resubmission","Not yet submitted")))))) -> Under review | G15: =IF($A15="","",IFERROR(INDEX(Submissions!$B$2:$B$1000,MATCH(_xlfn.MAXIFS(Submissions!$L$2:$L$1000,Submissions!$A$2:$A$1000,$A15),Submissions!$L$2:$L$1000,0)),"")) -> Critical Discourse Studies | H15: =IF($A15="","",IF(_xlfn.MAXIFS(Submissions!$F$2:$F$1000,Submissions!$A$2:$A$1000,$A15)=0,"",_xlfn.MAXIFS(Submissions!$F$2:$F$1000,Submissions!$A$2:$A$1000,$A15))) -> 46281 | I15: =IF($F15="Needs resubmission",IF($H15="","",TODAY()-$H15),"") | J15: =IF($A15="","",IF(_xlfn.MINIFS(Submissions!$M$2:$M$1000,Submissions!$A$2:$A$1000,$A15)=0,"",INDEX(Submissions!$B$2:$B$1000,_xlfn.MINIFS(Submissions!$M$2:$M$1000,Submissions!$A$2:$A$1000,$A15)-1))) -> Communication Theory | K15: =IF($A15="","",SUMIFS(Submissions!$J$2:$J$1000,Submissions!$A$2:$A$1000,$A15)) -> 16 | L15: =IF($A15="","",COUNTIFS(Submissions!$A$2:$A$1000,$A15,Submissions!$D$2:$D$1000,"Rejected")+COUNTIFS(Submissions!$A$2:$A$1000,$A15,Submissions!$D$2:$D$1000,"Returned by office")) -> 14 | M15: Earlier titles: Farmers’ Protest and the Language of Radical Passivity and Ethics – A Constructive Protest Communication Framework | …An Analytic Framework for Ethical Protest Communication. Word limits: Discourse Studies 8k, Social Movement Studies 8k, Ethics 12k. | N15: =IF(IF($F15="Revision due",3000,IF($F15="Needs resubmission",2000,IF($F15="Not yet submitted",1000,"")))="","",IF($F15="Revision due",3000,IF($F15="Needs resubmission",2000,IF($F15="Not yet submitted",1000,"")))+IF($I15="",0,MIN($I15,999))+(1000-ROW())/100000) | O15: =IF($N15="","",RANK($N15,$N$2:$N$81))
A16: Trust by Design (India engagement) | B16: Trust by Design: Fixing India’s Engagement Crisis | C16: Kaushal, S., Guha, A. | D16: Journal article | F16: =IF($A16="","",IF($E16<>"",$E16,IF(COUNTIFS(Submissions!$A$2:$A$1000,$A16,Submissions!$D$2:$D$1000,"Accepted")>0,"Accepted",IF(COUNTIFS(Submissions!$A$2:$A$1000,$A16,Submissions!$D$2:$D$1000,"Revision requested")>0,"Revision due",IF(COUNTIFS(Submissions!$A$2:$A$1000,$A16,Submissions!$D$2:$D$1000,"Under review")>0,"Under review",IF($K16>0,"Needs resubmission","Not yet submitted")))))) -> Needs resubmission | G16: =IF($A16="","",IFERROR(INDEX(Submissions!$B$2:$B$1000,MATCH(_xlfn.MAXIFS(Submissions!$L$2:$L$1000,Submissions!$A$2:$A$1000,$A16),Submissions!$L$2:$L$1000,0)),"")) -> Industrial and Commercial Training | H16: =IF($A16="","",IF(_xlfn.MAXIFS(Submissions!$F$2:$F$1000,Submissions!$A$2:$A$1000,$A16)=0,"",_xlfn.MAXIFS(Submissions!$F$2:$F$1000,Submissions!$A$2:$A$1000,$A16))) -> 45867 | I16: =IF($F16="Needs resubmission",IF($H16="","",TODAY()-$H16),"") -> 439 | J16: =IF($A16="","",IF(_xlfn.MINIFS(Submissions!$M$2:$M$1000,Submissions!$A$2:$A$1000,$A16)=0,"",INDEX(Submissions!$B$2:$B$1000,_xlfn.MINIFS(Submissions!$M$2:$M$1000,Submissions!$A$2:$A$1000,$A16)-1))) -> Strategic HR Review | K16: =IF($A16="","",SUMIFS(Submissions!$J$2:$J$1000,Submissions!$A$2:$A$1000,$A16)) -> 3 | L16: =IF($A16="","",COUNTIFS(Submissions!$A$2:$A$1000,$A16,Submissions!$D$2:$D$1000,"Rejected")+COUNTIFS(Submissions!$A$2:$A$1000,$A16,Submissions!$D$2:$D$1000,"Returned by office")) -> 3 | N16: =IF(IF($F16="Revision due",3000,IF($F16="Needs resubmission",2000,IF($F16="Not yet submitted",1000,"")))="","",IF($F16="Revision due",3000,IF($F16="Needs resubmission",2000,IF($F16="Not yet submitted",1000,"")))+IF($I16="",0,MIN($I16,999))+(1000-ROW())/100000) -> 2439.0098 | O16: =IF($N16="","",RANK($N16,$N$2:$N$81)) -> 1
A17: Is Leadership Inherently Violent? | B17: Is Leadership Inherently Violent? Sovereignty, Precarity, and the Ethics of Organizational Authority | C17: Kaushal, S., Guha, A. | D17: Journal article | F17: =IF($A17="","",IF($E17<>"",$E17,IF(COUNTIFS(Submissions!$A$2:$A$1000,$A17,Submissions!$D$2:$D$1000,"Accepted")>0,"Accepted",IF(COUNTIFS(Submissions!$A$2:$A$1000,$A17,Submissions!$D$2:$D$1000,"Revision requested")>0,"Revision due",IF(COUNTIFS(Submissions!$A$2:$A$1000,$A17,Submissions!$D$2:$D$1000,"Under review")>0,"Under review",IF($K17>0,"Needs resubmission","Not yet submitted")))))) -> Under review | G17: =IF($A17="","",IFERROR(INDEX(Submissions!$B$2:$B$1000,MATCH(_xlfn.MAXIFS(Submissions!$L$2:$L$1000,Submissions!$A$2:$A$1000,$A17),Submissions!$L$2:$L$1000,0)),"")) -> Journal of Business Ethics | H17: =IF($A17="","",IF(_xlfn.MAXIFS(Submissions!$F$2:$F$1000,Submissions!$A$2:$A$1000,$A17)=0,"",_xlfn.MAXIFS(Submissions!$F$2:$F$1000,Submissions!$A$2:$A$1000,$A17))) | I17: =IF($F17="Needs resubmission",IF($H17="","",TODAY()-$H17),"") | J17: =IF($A17="","",IF(_xlfn.MINIFS(Submissions!$M$2:$M$1000,Submissions!$A$2:$A$1000,$A17)=0,"",INDEX(Submissions!$B$2:$B$1000,_xlfn.MINIFS(Submissions!$M$2:$M$1000,Submissions!$A$2:$A$1000,$A17)-1))) -> Journal of Leadership and Organizational Studies | K17: =IF($A17="","",SUMIFS(Submissions!$J$2:$J$1000,Submissions!$A$2:$A$1000,$A17)) -> 1 | L17: =IF($A17="","",COUNTIFS(Submissions!$A$2:$A$1000,$A17,Submissions!$D$2:$D$1000,"Rejected")+COUNTIFS(Submissions!$A$2:$A$1000,$A17,Submissions!$D$2:$D$1000,"Returned by office")) -> 0 | N17: =IF(IF($F17="Revision due",3000,IF($F17="Needs resubmission",2000,IF($F17="Not yet submitted",1000,"")))="","",IF($F17="Revision due",3000,IF($F17="Needs resubmission",2000,IF($F17="Not yet submitted",1000,"")))+IF($I17="",0,MIN($I17,999))+(1000-ROW())/100000) | O17: =IF($N17="","",RANK($N17,$N$2:$N$81))
A18: Cosmoceuticals | B18: Cosmoceuticals | D18: Journal article | F18: =IF($A18="","",IF($E18<>"",$E18,IF(COUNTIFS(Submissions!$A$2:$A$1000,$A18,Submissions!$D$2:$D$1000,"Accepted")>0,"Accepted",IF(COUNTIFS(Submissions!$A$2:$A$1000,$A18,Submissions!$D$2:$D$1000,"Revision requested")>0,"Revision due",IF(COUNTIFS(Submissions!$A$2:$A$1000,$A18,Submissions!$D$2:$D$1000,"Under review")>0,"Under review",IF($K18>0,"Needs resubmission","Not yet submitted")))))) -> Under review | G18: =IF($A18="","",IFERROR(INDEX(Submissions!$B$2:$B$1000,MATCH(_xlfn.MAXIFS(Submissions!$L$2:$L$1000,Submissions!$A$2:$A$1000,$A18),Submissions!$L$2:$L$1000,0)),"")) -> IEEE Transactions on Engineering Management | H18: =IF($A18="","",IF(_xlfn.MAXIFS(Submissions!$F$2:$F$1000,Submissions!$A$2:$A$1000,$A18)=0,"",_xlfn.MAXIFS(Submissions!$F$2:$F$1000,Submissions!$A$2:$A$1000,$A18))) -> 46199 | I18: =IF($F18="Needs resubmission",IF($H18="","",TODAY()-$H18),"") | J18: =IF($A18="","",IF(_xlfn.MINIFS(Submissions!$M$2:$M$1000,Submissions!$A$2:$A$1000,$A18)=0,"",INDEX(Submissions!$B$2:$B$1000,_xlfn.MINIFS(Submissions!$M$2:$M$1000,Submissions!$A$2:$A$1000,$A18)-1))) -> journals.sagepub.com/home/con | K18: =IF($A18="","",SUMIFS(Submissions!$J$2:$J$1000,Submissions!$A$2:$A$1000,$A18)) -> 3 | L18: =IF($A18="","",COUNTIFS(Submissions!$A$2:$A$1000,$A18,Submissions!$D$2:$D$1000,"Rejected")+COUNTIFS(Submissions!$A$2:$A$1000,$A18,Submissions!$D$2:$D$1000,"Returned by office")) -> 2 | M18: Links in the old sheet are kept as journal names where the journal wasn’t written out. | N18: =IF(IF($F18="Revision due",3000,IF($F18="Needs resubmission",2000,IF($F18="Not yet submitted",1000,"")))="","",IF($F18="Revision due",3000,IF($F18="Needs resubmission",2000,IF($F18="Not yet submitted",1000,"")))+IF($I18="",0,MIN($I18,999))+(1000-ROW())/100000) | O18: =IF($N18="","",RANK($N18,$N$2:$N$81))
A19: Enhanced Athletes (EPW Letter) | B19: Communication Challenges in the Era of Enhanced Athletes | D19: EPW / short piece | E19: Closed – rejected | F19: =IF($A19="","",IF($E19<>"",$E19,IF(COUNTIFS(Submissions!$A$2:$A$1000,$A19,Submissions!$D$2:$D$1000,"Accepted")>0,"Accepted",IF(COUNTIFS(Submissions!$A$2:$A$1000,$A19,Submissions!$D$2:$D$1000,"Revision requested")>0,"Revision due",IF(COUNTIFS(Submissions!$A$2:$A$1000,$A19,Submissions!$D$2:$D$1000,"Under review")>0,"Under review",IF($K19>0,"Needs resubmission","Not yet submitted")))))) -> Closed – rejected | G19: =IF($A19="","",IFERROR(INDEX(Submissions!$B$2:$B$1000,MATCH(_xlfn.MAXIFS(Submissions!$L$2:$L$1000,Submissions!$A$2:$A$1000,$A19),Submissions!$L$2:$L$1000,0)),"")) -> EPW: Letter | H19: =IF($A19="","",IF(_xlfn.MAXIFS(Submissions!$F$2:$F$1000,Submissions!$A$2:$A$1000,$A19)=0,"",_xlfn.MAXIFS(Submissions!$F$2:$F$1000,Submissions!$A$2:$A$1000,$A19))) -> 45868 | I19: =IF($F19="Needs resubmission",IF($H19="","",TODAY()-$H19),"") | J19: =IF($A19="","",IF(_xlfn.MINIFS(Submissions!$M$2:$M$1000,Submissions!$A$2:$A$1000,$A19)=0,"",INDEX(Submissions!$B$2:$B$1000,_xlfn.MINIFS(Submissions!$M$2:$M$1000,Submissions!$A$2:$A$1000,$A19)-1))) | K19: =IF($A19="","",SUMIFS(Submissions!$J$2:$J$1000,Submissions!$A$2:$A$1000,$A19)) -> 1 | L19: =IF($A19="","",COUNTIFS(Submissions!$A$2:$A$1000,$A19,Submissions!$D$2:$D$1000,"Rejected")+COUNTIFS(Submissions!$A$2:$A$1000,$A19,Submissions!$D$2:$D$1000,"Returned by office")) -> 1 | N19: =IF(IF($F19="Revision due",3000,IF($F19="Needs resubmission",2000,IF($F19="Not yet submitted",1000,"")))="","",IF($F19="Revision due",3000,IF($F19="Needs resubmission",2000,IF($F19="Not yet submitted",1000,"")))+IF($I19="",0,MIN($I19,999))+(1000-ROW())/100000) | O19: =IF($N19="","",RANK($N19,$N$2:$N$81))
A20: Faith and the Other (EPW) | B20: Faith and the Other: Ethical Reflections on Ceremonial Communication | D20: EPW / short piece | E20: Closed – rejected | F20: =IF($A20="","",IF($E20<>"",$E20,IF(COUNTIFS(Submissions!$A$2:$A$1000,$A20,Submissions!$D$2:$D$1000,"Accepted")>0,"Accepted",IF(COUNTIFS(Submissions!$A$2:$A$1000,$A20,Submissions!$D$2:$D$1000,"Revision requested")>0,"Revision due",IF(COUNTIFS(Submissions!$A$2:$A$1000,$A20,Submissions!$D$2:$D$1000,"Under review")>0,"Under review",IF($K20>0,"Needs resubmission","Not yet submitted")))))) -> Closed – rejected | G20: =IF($A20="","",IFERROR(INDEX(Submissions!$B$2:$B$1000,MATCH(_xlfn.MAXIFS(Submissions!$L$2:$L$1000,Submissions!$A$2:$A$1000,$A20),Submissions!$L$2:$L$1000,0)),"")) -> EPW: Postscript | H20: =IF($A20="","",IF(_xlfn.MAXIFS(Submissions!$F$2:$F$1000,Submissions!$A$2:$A$1000,$A20)=0,"",_xlfn.MAXIFS(Submissions!$F$2:$F$1000,Submissions!$A$2:$A$1000,$A20))) -> 45699 | I20: =IF($F20="Needs resubmission",IF($H20="","",TODAY()-$H20),"") | J20: =IF($A20="","",IF(_xlfn.MINIFS(Submissions!$M$2:$M$1000,Submissions!$A$2:$A$1000,$A20)=0,"",INDEX(Submissions!$B$2:$B$1000,_xlfn.MINIFS(Submissions!$M$2:$M$1000,Submissions!$A$2:$A$1000,$A20)-1))) | K20: =IF($A20="","",SUMIFS(Submissions!$J$2:$J$1000,Submissions!$A$2:$A$1000,$A20)) -> 1 | L20: =IF($A20="","",COUNTIFS(Submissions!$A$2:$A$1000,$A20,Submissions!$D$2:$D$1000,"Rejected")+COUNTIFS(Submissions!$A$2:$A$1000,$A20,Submissions!$D$2:$D$1000,"Returned by office")) -> 1 | N20: =IF(IF($F20="Revision due",3000,IF($F20="Needs resubmission",2000,IF($F20="Not yet submitted",1000,"")))="","",IF($F20="Revision due",3000,IF($F20="Needs resubmission",2000,IF($F20="Not yet submitted",1000,"")))+IF($I20="",0,MIN($I20,999))+(1000-ROW())/100000) | O20: =IF($N20="","",RANK($N20,$N$2:$N$81))
A21: Coffee with the Machine (EPW) | B21: Coffee with the Machine: Sipping Meaning from Digital Tributaries | D21: EPW / short piece | E21: Closed – rejected | F21: =IF($A21="","",IF($E21<>"",$E21,IF(COUNTIFS(Submissions!$A$2:$A$1000,$A21,Submissions!$D$2:$D$1000,"Accepted")>0,"Accepted",IF(COUNTIFS(Submissions!$A$2:$A$1000,$A21,Submissions!$D$2:$D$1000,"Revision requested")>0,"Revision due",IF(COUNTIFS(Submissions!$A$2:$A$1000,$A21,Submissions!$D$2:$D$1000,"Under review")>0,"Under review",IF($K21>0,"Needs resubmission","Not yet submitted")))))) -> Closed – rejected | G21: =IF($A21="","",IFERROR(INDEX(Submissions!$B$2:$B$1000,MATCH(_xlfn.MAXIFS(Submissions!$L$2:$L$1000,Submissions!$A$2:$A$1000,$A21),Submissions!$L$2:$L$1000,0)),"")) -> EPW: Postscript | H21: =IF($A21="","",IF(_xlfn.MAXIFS(Submissions!$F$2:$F$1000,Submissions!$A$2:$A$1000,$A21)=0,"",_xlfn.MAXIFS(Submissions!$F$2:$F$1000,Submissions!$A$2:$A$1000,$A21))) -> 45965 | I21: =IF($F21="Needs resubmission",IF($H21="","",TODAY()-$H21),"") | J21: =IF($A21="","",IF(_xlfn.MINIFS(Submissions!$M$2:$M$1000,Submissions!$A$2:$A$1000,$A21)=0,"",INDEX(Submissions!$B$2:$B$1000,_xlfn.MINIFS(Submissions!$M$2:$M$1000,Submissions!$A$2:$A$1000,$A21)-1))) | K21: =IF($A21="","",SUMIFS(Submissions!$J$2:$J$1000,Submissions!$A$2:$A$1000,$A21)) -> 1 | L21: =IF($A21="","",COUNTIFS(Submissions!$A$2:$A$1000,$A21,Submissions!$D$2:$D$1000,"Rejected")+COUNTIFS(Submissions!$A$2:$A$1000,$A21,Submissions!$D$2:$D$1000,"Returned by office")) -> 1 | N21: =IF(IF($F21="Revision due",3000,IF($F21="Needs resubmission",2000,IF($F21="Not yet submitted",1000,"")))="","",IF($F21="Revision due",3000,IF($F21="Needs resubmission",2000,IF($F21="Not yet submitted",1000,"")))+IF($I21="",0,MIN($I21,999))+(1000-ROW())/100000) | O21: =IF($N21="","",RANK($N21,$N$2:$N$81))
A22: India’s Workplace Engagement Crisis (EPW) | B22: India’s Workplace Engagement Crisis | D22: EPW / short piece | E22: Closed – rejected | F22: =IF($A22="","",IF($E22<>"",$E22,IF(COUNTIFS(Submissions!$A$2:$A$1000,$A22,Submissions!$D$2:$D$1000,"Accepted")>0,"Accepted",IF(COUNTIFS(Submissions!$A$2:$A$1000,$A22,Submissions!$D$2:$D$1000,"Revision requested")>0,"Revision due",IF(COUNTIFS(Submissions!$A$2:$A$1000,$A22,Submissions!$D$2:$D$1000,"Under review")>0,"Under review",IF($K22>0,"Needs resubmission","Not yet submitted")))))) -> Closed – rejected | G22: =IF($A22="","",IFERROR(INDEX(Submissions!$B$2:$B$1000,MATCH(_xlfn.MAXIFS(Submissions!$L$2:$L$1000,Submissions!$A$2:$A$1000,$A22),Submissions!$L$2:$L$1000,0)),"")) -> EPW: Commentary | H22: =IF($A22="","",IF(_xlfn.MAXIFS(Submissions!$F$2:$F$1000,Submissions!$A$2:$A$1000,$A22)=0,"",_xlfn.MAXIFS(Submissions!$F$2:$F$1000,Submissions!$A$2:$A$1000,$A22))) -> 45922 | I22: =IF($F22="Needs resubmission",IF($H22="","",TODAY()-$H22),"") | J22: =IF($A22="","",IF(_xlfn.MINIFS(Submissions!$M$2:$M$1000,Submissions!$A$2:$A$1000,$A22)=0,"",INDEX(Submissions!$B$2:$B$1000,_xlfn.MINIFS(Submissions!$M$2:$M$1000,Submissions!$A$2:$A$1000,$A22)-1))) | K22: =IF($A22="","",SUMIFS(Submissions!$J$2:$J$1000,Submissions!$A$2:$A$1000,$A22)) -> 1 | L22: =IF($A22="","",COUNTIFS(Submissions!$A$2:$A$1000,$A22,Submissions!$D$2:$D$1000,"Rejected")+COUNTIFS(Submissions!$A$2:$A$1000,$A22,Submissions!$D$2:$D$1000,"Returned by office")) -> 1 | M22: EPW-only piece; not resubmitted elsewhere | N22: =IF(IF($F22="Revision due",3000,IF($F22="Needs resubmission",2000,IF($F22="Not yet submitted",1000,"")))="","",IF($F22="Revision due",3000,IF($F22="Needs resubmission",2000,IF($F22="Not yet submitted",1000,"")))+IF($I22="",0,MIN($I22,999))+(1000-ROW())/100000) | O22: =IF($N22="","",RANK($N22,$N$2:$N$81))
F23: =IF($A23="","",IF($E23<>"",$E23,IF(COUNTIFS(Submissions!$A$2:$A$1000,$A23,Submissions!$D$2:$D$1000,"Accepted")>0,"Accepted",IF(COUNTIFS(Submissions!$A$2:$A$1000,$A23,Submissions!$D$2:$D$1000,"Revision requested")>0,"Revision due",IF(COUNTIFS(Submissions!$A$2:$A$1000,$A23,Submissions!$D$2:$D$1000,"Under review")>0,"Under review",IF($K23>0,"Needs resubmission","Not yet submitted")))))) | G23: =IF($A23="","",IFERROR(INDEX(Submissions!$B$2:$B$1000,MATCH(_xlfn.MAXIFS(Submissions!$L$2:$L$1000,Submissions!$A$2:$A$1000,$A23),Submissions!$L$2:$L$1000,0)),"")) | H23: =IF($A23="","",IF(_xlfn.MAXIFS(Submissions!$F$2:$F$1000,Submissions!$A$2:$A$1000,$A23)=0,"",_xlfn.MAXIFS(Submissions!$F$2:$F$1000,Submissions!$A$2:$A$1000,$A23))) | I23: =IF($F23="Needs resubmission",IF($H23="","",TODAY()-$H23),"") | J23: =IF($A23="","",IF(_xlfn.MINIFS(Submissions!$M$2:$M$1000,Submissions!$A$2:$A$1000,$A23)=0,"",INDEX(Submissions!$B$2:$B$1000,_xlfn.MINIFS(Submissions!$M$2:$M$1000,Submissions!$A$2:$A$1000,$A23)-1))) | K23: =IF($A23="","",SUMIFS(Submissions!$J$2:$J$1000,Submissions!$A$2:$A$1000,$A23)) | L23: =IF($A23="","",COUNTIFS(Submissions!$A$2:$A$1000,$A23,Submissions!$D$2:$D$1000,"Rejected")+COUNTIFS(Submissions!$A$2:$A$1000,$A23,Submissions!$D$2:$D$1000,"Returned by office")) | N23: =IF(IF($F23="Revision due",3000,IF($F23="Needs resubmission",2000,IF($F23="Not yet submitted",1000,"")))="","",IF($F23="Revision due",3000,IF($F23="Needs resubmission",2000,IF($F23="Not yet submitted",1000,"")))+IF($I23="",0,MIN($I23,999))+(1000-ROW())/100000) | O23: =IF($N23="","",RANK($N23,$N$2:$N$81))
F24: =IF($A24="","",IF($E24<>"",$E24,IF(COUNTIFS(Submissions!$A$2:$A$1000,$A24,Submissions!$D$2:$D$1000,"Accepted")>0,"Accepted",IF(COUNTIFS(Submissions!$A$2:$A$1000,$A24,Submissions!$D$2:$D$1000,"Revision requested")>0,"Revision due",IF(COUNTIFS(Submissions!$A$2:$A$1000,$A24,Submissions!$D$2:$D$1000,"Under review")>0,"Under review",IF($K24>0,"Needs resubmission","Not yet submitted")))))) | G24: =IF($A24="","",IFERROR(INDEX(Submissions!$B$2:$B$1000,MATCH(_xlfn.MAXIFS(Submissions!$L$2:$L$1000,Submissions!$A$2:$A$1000,$A24),Submissions!$L$2:$L$1000,0)),"")) | H24: =IF($A24="","",IF(_xlfn.MAXIFS(Submissions!$F$2:$F$1000,Submissions!$A$2:$A$1000,$A24)=0,"",_xlfn.MAXIFS(Submissions!$F$2:$F$1000,Submissions!$A$2:$A$1000,$A24))) | I24: =IF($F24="Needs resubmission",IF($H24="","",TODAY()-$H24),"") | J24: =IF($A24="","",IF(_xlfn.MINIFS(Submissions!$M$2:$M$1000,Submissions!$A$2:$A$1000,$A24)=0,"",INDEX(Submissions!$B$2:$B$1000,_xlfn.MINIFS(Submissions!$M$2:$M$1000,Submissions!$A$2:$A$1000,$A24)-1))) | K24: =IF($A24="","",SUMIFS(Submissions!$J$2:$J$1000,Submissions!$A$2:$A$1000,$A24)) | L24: =IF($A24="","",COUNTIFS(Submissions!$A$2:$A$1000,$A24,Submissions!$D$2:$D$1000,"Rejected")+COUNTIFS(Submissions!$A$2:$A$1000,$A24,Submissions!$D$2:$D$1000,"Returned by office")) | N24: =IF(IF($F24="Revision due",3000,IF($F24="Needs resubmission",2000,IF($F24="Not yet submitted",1000,"")))="","",IF($F24="Revision due",3000,IF($F24="Needs resubmission",2000,IF($F24="Not yet submitted",1000,"")))+IF($I24="",0,MIN($I24,999))+(1000-ROW())/100000) | O24: =IF($N24="","",RANK($N24,$N$2:$N$81))
