Workbook

Sheet Dashboard
B2: SK research submissions
B3: ="As of "&TEXT(TODAY(),"d mmm yyyy")&" · edit Submissions, Papers and Journals; this page updates itself" | G3: Chase editor after (days): | H3: 90
B5: PAPERS TRACKED | C5: UNDER REVIEW | E5: WAITING ON YOU | G5: SUBMISSIONS SENT | H5: ACCEPTED
B6: =COUNTIFS(Papers!$A$2:$A$200,"<>",Papers!$G$2:$G$200,"<>Parked",Papers!$G$2:$G$200,"<>Closed – rejected",Papers!$G$2:$G$200,"<>Withdrawn",Papers!$G$2:$G$200,"<>Published") | C6: =COUNTIF(Submissions!$E:$E,"Under review") | E6: =COUNTIF(Papers!$G$2:$G$200,"Revision due")+COUNTIF(Papers!$G$2:$G$200,"Needs resubmission")+COUNTIF(Papers!$G$2:$G$200,"Not yet submitted") | G6: =SUMPRODUCT((Submissions!$B$2:$B$2000<>"")*(Submissions!$E$2:$E$2000<>"Planned")) | H6: =COUNTIF(Submissions!$E:$E,"Accepted")
B9: Under review now (longest wait first)
B10: PAPER | C10: JOURNAL | D10: ABDC | E10: SUBMITTED | F10: DAYS | G10: CHECK | H10: ON JOURNAL SITE
B11: =IFERROR(INDEX(Submissions!$A:$A,MATCH(1,Submissions!$P:$P,0))&"","") | C11: =IFERROR(INDEX(Submissions!$B:$B,MATCH(1,Submissions!$P:$P,0))&"","") | D11: =IFERROR(INDEX(Submissions!$C:$C,MATCH(1,Submissions!$P:$P,0))&"","") | E11: =IFERROR(INDEX(Submissions!$F:$F,MATCH(1,Submissions!$P:$P,0)),"") | F11: =IFERROR(INDEX(Submissions!$H:$H,MATCH(1,Submissions!$P:$P,0)),"") | G11: =IF(F11="","",IF(F11>=2*$H$3,"Overdue: chase editor",IF(F11>=$H$3,"Check status",""))) | H11: =IFERROR(INDEX(Submissions!$L:$L,MATCH(1,Submissions!$P:$P,0))&"","")
B12: =IFERROR(INDEX(Submissions!$A:$A,MATCH(2,Submissions!$P:$P,0))&"","") | C12: =IFERROR(INDEX(Submissions!$B:$B,MATCH(2,Submissions!$P:$P,0))&"","") | D12: =IFERROR(INDEX(Submissions!$C:$C,MATCH(2,Submissions!$P:$P,0))&"","") | E12: =IFERROR(INDEX(Submissions!$F:$F,MATCH(2,Submissions!$P:$P,0)),"") | F12: =IFERROR(INDEX(Submissions!$H:$H,MATCH(2,Submissions!$P:$P,0)),"") | G12: =IF(F12="","",IF(F12>=2*$H$3,"Overdue: chase editor",IF(F12>=$H$3,"Check status",""))) | H12: =IFERROR(INDEX(Submissions!$L:$L,MATCH(2,Submissions!$P:$P,0))&"","")
B13: =IFERROR(INDEX(Submissions!$A:$A,MATCH(3,Submissions!$P:$P,0))&"","") | C13: =IFERROR(INDEX(Submissions!$B:$B,MATCH(3,Submissions!$P:$P,0))&"","") | D13: =IFERROR(INDEX(Submissions!$C:$C,MATCH(3,Submissions!$P:$P,0))&"","") | E13: =IFERROR(INDEX(Submissions!$F:$F,MATCH(3,Submissions!$P:$P,0)),"") | F13: =IFERROR(INDEX(Submissions!$H:$H,MATCH(3,Submissions!$P:$P,0)),"") | G13: =IF(F13="","",IF(F13>=2*$H$3,"Overdue: chase editor",IF(F13>=$H$3,"Check status",""))) | H13: =IFERROR(INDEX(Submissions!$L:$L,MATCH(3,Submissions!$P:$P,0))&"","")
B14: =IFERROR(INDEX(Submissions!$A:$A,MATCH(4,Submissions!$P:$P,0))&"","") | C14: =IFERROR(INDEX(Submissions!$B:$B,MATCH(4,Submissions!$P:$P,0))&"","") | D14: =IFERROR(INDEX(Submissions!$C:$C,MATCH(4,Submissions!$P:$P,0))&"","") | E14: =IFERROR(INDEX(Submissions!$F:$F,MATCH(4,Submissions!$P:$P,0)),"") | F14: =IFERROR(INDEX(Submissions!$H:$H,MATCH(4,Submissions!$P:$P,0)),"") | G14: =IF(F14="","",IF(F14>=2*$H$3,"Overdue: chase editor",IF(F14>=$H$3,"Check status",""))) | H14: =IFERROR(INDEX(Submissions!$L:$L,MATCH(4,Submissions!$P:$P,0))&"","")
B15: =IFERROR(INDEX(Submissions!$A:$A,MATCH(5,Submissions!$P:$P,0))&"","") | C15: =IFERROR(INDEX(Submissions!$B:$B,MATCH(5,Submissions!$P:$P,0))&"","") | D15: =IFERROR(INDEX(Submissions!$C:$C,MATCH(5,Submissions!$P:$P,0))&"","") | E15: =IFERROR(INDEX(Submissions!$F:$F,MATCH(5,Submissions!$P:$P,0)),"") | F15: =IFERROR(INDEX(Submissions!$H:$H,MATCH(5,Submissions!$P:$P,0)),"") | G15: =IF(F15="","",IF(F15>=2*$H$3,"Overdue: chase editor",IF(F15>=$H$3,"Check status",""))) | H15: =IFERROR(INDEX(Submissions!$L:$L,MATCH(5,Submissions!$P:$P,0))&"","")
B16: =IFERROR(INDEX(Submissions!$A:$A,MATCH(6,Submissions!$P:$P,0))&"","") | C16: =IFERROR(INDEX(Submissions!$B:$B,MATCH(6,Submissions!$P:$P,0))&"","") | D16: =IFERROR(INDEX(Submissions!$C:$C,MATCH(6,Submissions!$P:$P,0))&"","") | E16: =IFERROR(INDEX(Submissions!$F:$F,MATCH(6,Submissions!$P:$P,0)),"") | F16: =IFERROR(INDEX(Submissions!$H:$H,MATCH(6,Submissions!$P:$P,0)),"") | G16: =IF(F16="","",IF(F16>=2*$H$3,"Overdue: chase editor",IF(F16>=$H$3,"Check status",""))) | H16: =IFERROR(INDEX(Submissions!$L:$L,MATCH(6,Submissions!$P:$P,0))&"","")
B17: =IFERROR(INDEX(Submissions!$A:$A,MATCH(7,Submissions!$P:$P,0))&"","") | C17: =IFERROR(INDEX(Submissions!$B:$B,MATCH(7,Submissions!$P:$P,0))&"","") | D17: =IFERROR(INDEX(Submissions!$C:$C,MATCH(7,Submissions!$P:$P,0))&"","") | E17: =IFERROR(INDEX(Submissions!$F:$F,MATCH(7,Submissions!$P:$P,0)),"") | F17: =IFERROR(INDEX(Submissions!$H:$H,MATCH(7,Submissions!$P:$P,0)),"") | G17: =IF(F17="","",IF(F17>=2*$H$3,"Overdue: chase editor",IF(F17>=$H$3,"Check status",""))) | H17: =IFERROR(INDEX(Submissions!$L:$L,MATCH(7,Submissions!$P:$P,0))&"","")
B18: =IFERROR(INDEX(Submissions!$A:$A,MATCH(8,Submissions!$P:$P,0))&"","") | C18: =IFERROR(INDEX(Submissions!$B:$B,MATCH(8,Submissions!$P:$P,0))&"","") | D18: =IFERROR(INDEX(Submissions!$C:$C,MATCH(8,Submissions!$P:$P,0))&"","") | E18: =IFERROR(INDEX(Submissions!$F:$F,MATCH(8,Submissions!$P:$P,0)),"") | F18: =IFERROR(INDEX(Submissions!$H:$H,MATCH(8,Submissions!$P:$P,0)),"") | G18: =IF(F18="","",IF(F18>=2*$H$3,"Overdue: chase editor",IF(F18>=$H$3,"Check status",""))) | H18: =IFERROR(INDEX(Submissions!$L:$L,MATCH(8,Submissions!$P:$P,0))&"","")
B19: =IFERROR(INDEX(Submissions!$A:$A,MATCH(9,Submissions!$P:$P,0))&"","") | C19: =IFERROR(INDEX(Submissions!$B:$B,MATCH(9,Submissions!$P:$P,0))&"","") | D19: =IFERROR(INDEX(Submissions!$C:$C,MATCH(9,Submissions!$P:$P,0))&"","") | E19: =IFERROR(INDEX(Submissions!$F:$F,MATCH(9,Submissions!$P:$P,0)),"") | F19: =IFERROR(INDEX(Submissions!$H:$H,MATCH(9,Submissions!$P:$P,0)),"") | G19: =IF(F19="","",IF(F19>=2*$H$3,"Overdue: chase editor",IF(F19>=$H$3,"Check status",""))) | H19: =IFERROR(INDEX(Submissions!$L:$L,MATCH(9,Submissions!$P:$P,0))&"","")
B20: =IFERROR(INDEX(Submissions!$A:$A,MATCH(10,Submissions!$P:$P,0))&"","") | C20: =IFERROR(INDEX(Submissions!$B:$B,MATCH(10,Submissions!$P:$P,0))&"","") | D20: =IFERROR(INDEX(Submissions!$C:$C,MATCH(10,Submissions!$P:$P,0))&"","") | E20: =IFERROR(INDEX(Submissions!$F:$F,MATCH(10,Submissions!$P:$P,0)),"") | F20: =IFERROR(INDEX(Submissions!$H:$H,MATCH(10,Submissions!$P:$P,0)),"") | G20: =IF(F20="","",IF(F20>=2*$H$3,"Overdue: chase editor",IF(F20>=$H$3,"Check status",""))) | H20: =IFERROR(INDEX(Submissions!$L:$L,MATCH(10,Submissions!$P:$P,0))&"","")
B21: =IFERROR(INDEX(Submissions!$A:$A,MATCH(11,Submissions!$P:$P,0))&"","") | C21: =IFERROR(INDEX(Submissions!$B:$B,MATCH(11,Submissions!$P:$P,0))&"","") | D21: =IFERROR(INDEX(Submissions!$C:$C,MATCH(11,Submissions!$P:$P,0))&"","") | E21: =IFERROR(INDEX(Submissions!$F:$F,MATCH(11,Submissions!$P:$P,0)),"") | F21: =IFERROR(INDEX(Submissions!$H:$H,MATCH(11,Submissions!$P:$P,0)),"") | G21: =IF(F21="","",IF(F21>=2*$H$3,"Overdue: chase editor",IF(F21>=$H$3,"Check status",""))) | H21: =IFERROR(INDEX(Submissions!$L:$L,MATCH(11,Submissions!$P:$P,0))&"","")
B22: =IFERROR(INDEX(Submissions!$A:$A,MATCH(12,Submissions!$P:$P,0))&"","") | C22: =IFERROR(INDEX(Submissions!$B:$B,MATCH(12,Submissions!$P:$P,0))&"","") | D22: =IFERROR(INDEX(Submissions!$C:$C,MATCH(12,Submissions!$P:$P,0))&"","") | E22: =IFERROR(INDEX(Submissions!$F:$F,MATCH(12,Submissions!$P:$P,0)),"") | F22: =IFERROR(INDEX(Submissions!$H:$H,MATCH(12,Submissions!$P:$P,0)),"") | G22: =IF(F22="","",IF(F22>=2*$H$3,"Overdue: chase editor",IF(F22>=$H$3,"Check status",""))) | H22: =IFERROR(INDEX(Submissions!$L:$L,MATCH(12,Submissions!$P:$P,0))&"","")
B23: =IFERROR(INDEX(Submissions!$A:$A,MATCH(13,Submissions!$P:$P,0))&"","") | C23: =IFERROR(INDEX(Submissions!$B:$B,MATCH(13,Submissions!$P:$P,0))&"","") | D23: =IFERROR(INDEX(Submissions!$C:$C,MATCH(13,Submissions!$P:$P,0))&"","") | E23: =IFERROR(INDEX(Submissions!$F:$F,MATCH(13,Submissions!$P:$P,0)),"") | F23: =IFERROR(INDEX(Submissions!$H:$H,MATCH(13,Submissions!$P:$P,0)),"") | G23: =IF(F23="","",IF(F23>=2*$H$3,"Overdue: chase editor",IF(F23>=$H$3,"Check status",""))) | H23: =IFERROR(INDEX(Submissions!$L:$L,MATCH(13,Submissions!$P:$P,0))&"","")
B24: =IFERROR(INDEX(Submissions!$A:$A,MATCH(14,Submissions!$P:$P,0))&"","") | C24: =IFERROR(INDEX(Submissions!$B:$B,MATCH(14,Submissions!$P:$P,0))&"","") | D24: =IFERROR(INDEX(Submissions!$C:$C,MATCH(14,Submissions!$P:$P,0))&"","") | E24: =IFERROR(INDEX(Submissions!$F:$F,MATCH(14,Submissions!$P:$P,0)),"") | F24: =IFERROR(INDEX(Submissions!$H:$H,MATCH(14,Submissions!$P:$P,0)),"") | G24: =IF(F24="","",IF(F24>=2*$H$3,"Overdue: chase editor",IF(F24>=$H$3,"Check status",""))) | H24: =IFERROR(INDEX(Submissions!$L:$L,MATCH(14,Submissions!$P:$P,0))&"","")
B25: =IFERROR(INDEX(Submissions!$A:$A,MATCH(15,Submissions!$P:$P,0))&"","") | C25: =IFERROR(INDEX(Submissions!$B:$B,MATCH(15,Submissions!$P:$P,0))&"","") | D25: =IFERROR(INDEX(Submissions!$C:$C,MATCH(15,Submissions!$P:$P,0))&"","") | E25: =IFERROR(INDEX(Submissions!$F:$F,MATCH(15,Submissions!$P:$P,0)),"") | F25: =IFERROR(INDEX(Submissions!$H:$H,MATCH(15,Submissions!$P:$P,0)),"") | G25: =IF(F25="","",IF(F25>=2*$H$3,"Overdue: chase editor",IF(F25>=$H$3,"Check status",""))) | H25: =IFERROR(INDEX(Submissions!$L:$L,MATCH(15,Submissions!$P:$P,0))&"","")
B26: =IFERROR(INDEX(Submissions!$A:$A,MATCH(16,Submissions!$P:$P,0))&"","") | C26: =IFERROR(INDEX(Submissions!$B:$B,MATCH(16,Submissions!$P:$P,0))&"","") | D26: =IFERROR(INDEX(Submissions!$C:$C,MATCH(16,Submissions!$P:$P,0))&"","") | E26: =IFERROR(INDEX(Submissions!$F:$F,MATCH(16,Submissions!$P:$P,0)),"") | F26: =IFERROR(INDEX(Submissions!$H:$H,MATCH(16,Submissions!$P:$P,0)),"") | G26: =IF(F26="","",IF(F26>=2*$H$3,"Overdue: chase editor",IF(F26>=$H$3,"Check status",""))) | H26: =IFERROR(INDEX(Submissions!$L:$L,MATCH(16,Submissions!$P:$P,0))&"","")
B27: =IFERROR(INDEX(Submissions!$A:$A,MATCH(17,Submissions!$P:$P,0))&"","") | C27: =IFERROR(INDEX(Submissions!$B:$B,MATCH(17,Submissions!$P:$P,0))&"","") | D27: =IFERROR(INDEX(Submissions!$C:$C,MATCH(17,Submissions!$P:$P,0))&"","") | E27: =IFERROR(INDEX(Submissions!$F:$F,MATCH(17,Submissions!$P:$P,0)),"") | F27: =IFERROR(INDEX(Submissions!$H:$H,MATCH(17,Submissions!$P:$P,0)),"") | G27: =IF(F27="","",IF(F27>=2*$H$3,"Overdue: chase editor",IF(F27>=$H$3,"Check status",""))) | H27: =IFERROR(INDEX(Submissions!$L:$L,MATCH(17,Submissions!$P:$P,0))&"","")
B28: =IFERROR(INDEX(Submissions!$A:$A,MATCH(18,Submissions!$P:$P,0))&"","") | C28: =IFERROR(INDEX(Submissions!$B:$B,MATCH(18,Submissions!$P:$P,0))&"","") | D28: =IFERROR(INDEX(Submissions!$C:$C,MATCH(18,Submissions!$P:$P,0))&"","") | E28: =IFERROR(INDEX(Submissions!$F:$F,MATCH(18,Submissions!$P:$P,0)),"") | F28: =IFERROR(INDEX(Submissions!$H:$H,MATCH(18,Submissions!$P:$P,0)),"") | G28: =IF(F28="","",IF(F28>=2*$H$3,"Overdue: chase editor",IF(F28>=$H$3,"Check status",""))) | H28: =IFERROR(INDEX(Submissions!$L:$L,MATCH(18,Submissions!$P:$P,0))&"","")
B29: =IFERROR(INDEX(Submissions!$A:$A,MATCH(19,Submissions!$P:$P,0))&"","") | C29: =IFERROR(INDEX(Submissions!$B:$B,MATCH(19,Submissions!$P:$P,0))&"","") | D29: =IFERROR(INDEX(Submissions!$C:$C,MATCH(19,Submissions!$P:$P,0))&"","") | E29: =IFERROR(INDEX(Submissions!$F:$F,MATCH(19,Submissions!$P:$P,0)),"") | F29: =IFERROR(INDEX(Submissions!$H:$H,MATCH(19,Submissions!$P:$P,0)),"") | G29: =IF(F29="","",IF(F29>=2*$H$3,"Overdue: chase editor",IF(F29>=$H$3,"Check status",""))) | H29: =IFERROR(INDEX(Submissions!$L:$L,MATCH(19,Submissions!$P:$P,0))&"","")
B30: =IFERROR(INDEX(Submissions!$A:$A,MATCH(20,Submissions!$P:$P,0))&"","") | C30: =IFERROR(INDEX(Submissions!$B:$B,MATCH(20,Submissions!$P:$P,0))&"","") | D30: =IFERROR(INDEX(Submissions!$C:$C,MATCH(20,Submissions!$P:$P,0))&"","") | E30: =IFERROR(INDEX(Submissions!$F:$F,MATCH(20,Submissions!$P:$P,0)),"") | F30: =IFERROR(INDEX(Submissions!$H:$H,MATCH(20,Submissions!$P:$P,0)),"") | G30: =IF(F30="","",IF(F30>=2*$H$3,"Overdue: chase editor",IF(F30>=$H$3,"Check status",""))) | H30: =IFERROR(INDEX(Submissions!$L:$L,MATCH(20,Submissions!$P:$P,0))&"","")
B31: =IFERROR(INDEX(Submissions!$A:$A,MATCH(21,Submissions!$P:$P,0))&"","") | C31: =IFERROR(INDEX(Submissions!$B:$B,MATCH(21,Submissions!$P:$P,0))&"","") | D31: =IFERROR(INDEX(Submissions!$C:$C,MATCH(21,Submissions!$P:$P,0))&"","") | E31: =IFERROR(INDEX(Submissions!$F:$F,MATCH(21,Submissions!$P:$P,0)),"") | F31: =IFERROR(INDEX(Submissions!$H:$H,MATCH(21,Submissions!$P:$P,0)),"") | G31: =IF(F31="","",IF(F31>=2*$H$3,"Overdue: chase editor",IF(F31>=$H$3,"Check status",""))) | H31: =IFERROR(INDEX(Submissions!$L:$L,MATCH(21,Submissions!$P:$P,0))&"","")
B32: =IFERROR(INDEX(Submissions!$A:$A,MATCH(22,Submissions!$P:$P,0))&"","") | C32: =IFERROR(INDEX(Submissions!$B:$B,MATCH(22,Submissions!$P:$P,0))&"","") | D32: =IFERROR(INDEX(Submissions!$C:$C,MATCH(22,Submissions!$P:$P,0))&"","") | E32: =IFERROR(INDEX(Submissions!$F:$F,MATCH(22,Submissions!$P:$P,0)),"") | F32: =IFERROR(INDEX(Submissions!$H:$H,MATCH(22,Submissions!$P:$P,0)),"") | G32: =IF(F32="","",IF(F32>=2*$H$3,"Overdue: chase editor",IF(F32>=$H$3,"Check status",""))) | H32: =IFERROR(INDEX(Submissions!$L:$L,MATCH(22,Submissions!$P:$P,0))&"","")
B33: =IFERROR(INDEX(Submissions!$A:$A,MATCH(23,Submissions!$P:$P,0))&"","") | C33: =IFERROR(INDEX(Submissions!$B:$B,MATCH(23,Submissions!$P:$P,0))&"","") | D33: =IFERROR(INDEX(Submissions!$C:$C,MATCH(23,Submissions!$P:$P,0))&"","") | E33: =IFERROR(INDEX(Submissions!$F:$F,MATCH(23,Submissions!$P:$P,0)),"") | F33: =IFERROR(INDEX(Submissions!$H:$H,MATCH(23,Submissions!$P:$P,0)),"") | G33: =IF(F33="","",IF(F33>=2*$H$3,"Overdue: chase editor",IF(F33>=$H$3,"Check status",""))) | H33: =IFERROR(INDEX(Submissions!$L:$L,MATCH(23,Submissions!$P:$P,0))&"","")
B34: =IFERROR(INDEX(Submissions!$A:$A,MATCH(24,Submissions!$P:$P,0))&"","") | C34: =IFERROR(INDEX(Submissions!$B:$B,MATCH(24,Submissions!$P:$P,0))&"","") | D34: =IFERROR(INDEX(Submissions!$C:$C,MATCH(24,Submissions!$P:$P,0))&"","") | E34: =IFERROR(INDEX(Submissions!$F:$F,MATCH(24,Submissions!$P:$P,0)),"") | F34: =IFERROR(INDEX(Submissions!$H:$H,MATCH(24,Submissions!$P:$P,0)),"") | G34: =IF(F34="","",IF(F34>=2*$H$3,"Overdue: chase editor",IF(F34>=$H$3,"Check status",""))) | H34: =IFERROR(INDEX(Submissions!$L:$L,MATCH(24,Submissions!$P:$P,0))&"","")
B35: =IFERROR(INDEX(Submissions!$A:$A,MATCH(25,Submissions!$P:$P,0))&"","") | C35: =IFERROR(INDEX(Submissions!$B:$B,MATCH(25,Submissions!$P:$P,0))&"","") | D35: =IFERROR(INDEX(Submissions!$C:$C,MATCH(25,Submissions!$P:$P,0))&"","") | E35: =IFERROR(INDEX(Submissions!$F:$F,MATCH(25,Submissions!$P:$P,0)),"") | F35: =IFERROR(INDEX(Submissions!$H:$H,MATCH(25,Submissions!$P:$P,0)),"") | G35: =IF(F35="","",IF(F35>=2*$H$3,"Overdue: chase editor",IF(F35>=$H$3,"Check status",""))) | H35: =IFERROR(INDEX(Submissions!$L:$L,MATCH(25,Submissions!$P:$P,0))&"","")
B38: Waiting on you (revisions first, then papers to resubmit, then not yet submitted)
B39: PAPER | C39: STAGE | E39: NEXT IN YOUR QUEUE | G39: SUGGESTED (ABDC)
B40: =IFERROR(INDEX(Papers!$A:$A,MATCH(1,Papers!$O:$O,0))&"","") | C40: =IFERROR(INDEX(Papers!$G:$G,MATCH(1,Papers!$O:$O,0))&"","") | E40: =IFERROR(INDEX(Papers!$K:$K,MATCH(1,Papers!$O:$O,0))&"","") | G40: =IFERROR(INDEX(Papers!$L:$L,MATCH(1,Papers!$O:$O,0))&"","")
B41: =IFERROR(INDEX(Papers!$A:$A,MATCH(2,Papers!$O:$O,0))&"","") | C41: =IFERROR(INDEX(Papers!$G:$G,MATCH(2,Papers!$O:$O,0))&"","") | E41: =IFERROR(INDEX(Papers!$K:$K,MATCH(2,Papers!$O:$O,0))&"","") | G41: =IFERROR(INDEX(Papers!$L:$L,MATCH(2,Papers!$O:$O,0))&"","")
B42: =IFERROR(INDEX(Papers!$A:$A,MATCH(3,Papers!$O:$O,0))&"","") | C42: =IFERROR(INDEX(Papers!$G:$G,MATCH(3,Papers!$O:$O,0))&"","") | E42: =IFERROR(INDEX(Papers!$K:$K,MATCH(3,Papers!$O:$O,0))&"","") | G42: =IFERROR(INDEX(Papers!$L:$L,MATCH(3,Papers!$O:$O,0))&"","")
B43: =IFERROR(INDEX(Papers!$A:$A,MATCH(4,Papers!$O:$O,0))&"","") | C43: =IFERROR(INDEX(Papers!$G:$G,MATCH(4,Papers!$O:$O,0))&"","") | E43: =IFERROR(INDEX(Papers!$K:$K,MATCH(4,Papers!$O:$O,0))&"","") | G43: =IFERROR(INDEX(Papers!$L:$L,MATCH(4,Papers!$O:$O,0))&"","")
B44: =IFERROR(INDEX(Papers!$A:$A,MATCH(5,Papers!$O:$O,0))&"","") | C44: =IFERROR(INDEX(Papers!$G:$G,MATCH(5,Papers!$O:$O,0))&"","") | E44: =IFERROR(INDEX(Papers!$K:$K,MATCH(5,Papers!$O:$O,0))&"","") | G44: =IFERROR(INDEX(Papers!$L:$L,MATCH(5,Papers!$O:$O,0))&"","")
B45: =IFERROR(INDEX(Papers!$A:$A,MATCH(6,Papers!$O:$O,0))&"","") | C45: =IFERROR(INDEX(Papers!$G:$G,MATCH(6,Papers!$O:$O,0))&"","") | E45: =IFERROR(INDEX(Papers!$K:$K,MATCH(6,Papers!$O:$O,0))&"","") | G45: =IFERROR(INDEX(Papers!$L:$L,MATCH(6,Papers!$O:$O,0))&"","")
B46: =IFERROR(INDEX(Papers!$A:$A,MATCH(7,Papers!$O:$O,0))&"","") | C46: =IFERROR(INDEX(Papers!$G:$G,MATCH(7,Papers!$O:$O,0))&"","") | E46: =IFERROR(INDEX(Papers!$K:$K,MATCH(7,Papers!$O:$O,0))&"","") | G46: =IFERROR(INDEX(Papers!$L:$L,MATCH(7,Papers!$O:$O,0))&"","")
...

Sheet How to use
A1: How to use this master sheet
A3: Submissions | B3: The master list, grouped by paper. Each paper has a shaded heading row, then its journals (history first, then the current one, then the planned queue), then empty rows for future submissions.
A4: After a rejection | B4: Change that row's Status to Rejected and fill Date of decision. Then use an empty row under the paper: pick the Paper from the list, type or pick the Journal, set Status = Under review and the date.
A5: A new journal to try later | B5: Add a row with Status = Planned (no dates). The first Planned row of a paper is its ‘Next in queue’.
A6: ABDC rating | B6: Filled automatically from the Journals tab (official ABDC list, 2025 ratings). ‘Not listed’ = not on the 2025 list; the 2022 rating is shown there when it differs. New journal? Add it on the Journals tab.
A7: Papers | B7: One row per paper: short name (must be unique), title, authors. Stage, current journal and counts are calculated.
A8: Journals | B8: One row per journal: ABDC rating (automatic from the ABDC list tab), login link and editorial office email (the app uses these too). If a journal shows ‘Not listed’ but is on the list under another name, pick that name in ‘Name on ABDC list’.
A9: Suggested next journals | B9: Papers tab: ABDC journals that fit each paper (same ABDC fields as the journals you chose, matching topic words, around the tier of the last journal). Refreshed on every app sync, or from the menu RD SK → Refresh suggested journals. Your own Planned queue always comes first.
A10: Don't edit | B10: Grey/automatic columns (ABDC, Days) and the hidden columns (App ID, Updated, helpers) are managed for you.
A11: Phone app | B11: RD SK keeps this sheet in sync: sign in with this Google account in the app (More → Google account). Changes on either side appear on the other. After reinstalling, just sign in again.
A12: Email import & insights | B12: Optional: Extensions → Apps Script, paste the RD SK helper script (copy it from the app: More → Email import helper), save, reload this sheet, then use the RD SK menu.

Sheet Submissions
A1: Paper | B1: Journal | C1: ABDC 2025 | D1: Other rating / index | E1: Status | F1: Date submitted | G1: Date of decision | H1: Days | I1: Notes | J1: Title used | K1: Manuscript ID | L1: Status on journal site | M1: Status checked | N1: App ID | O1: Updated | P1: ur rank | Q1: paper|status
C2: =IF(B2="","",IFERROR(VLOOKUP(B2,Journals!$A:$B,2,FALSE),IFERROR(VLOOKUP(B2,'ABDC list'!$A:$B,2,FALSE),""))) | H2: =IF(OR(F2="",E2="Planned"),"",IF(G2<>"",G2-F2,TODAY()-F2)) | P2: =IF(E2="Under review",COUNTIFS($E:$E,"Under review",$F:$F,"<"&F2)+COUNTIFS($E$1:E2,"Under review",$F$1:F2,F2),"") | Q2: =IF(B2="","",A2&"|"&E2)
C3: =IF(B3="","",IFERROR(VLOOKUP(B3,Journals!$A:$B,2,FALSE),IFERROR(VLOOKUP(B3,'ABDC list'!$A:$B,2,FALSE),""))) | H3: =IF(OR(F3="",E3="Planned"),"",IF(G3<>"",G3-F3,TODAY()-F3)) | P3: =IF(E3="Under review",COUNTIFS($E:$E,"Under review",$F:$F,"<"&F3)+COUNTIFS($E$1:E3,"Under review",$F$1:F3,F3),"") | Q3: =IF(B3="","",A3&"|"&E3)
C4: =IF(B4="","",IFERROR(VLOOKUP(B4,Journals!$A:$B,2,FALSE),IFERROR(VLOOKUP(B4,'ABDC list'!$A:$B,2,FALSE),""))) | H4: =IF(OR(F4="",E4="Planned"),"",IF(G4<>"",G4-F4,TODAY()-F4)) | P4: =IF(E4="Under review",COUNTIFS($E:$E,"Under review",$F:$F,"<"&F4)+COUNTIFS($E$1:E4,"Under review",$F$1:F4,F4),"") | Q4: =IF(B4="","",A4&"|"&E4)
C5: =IF(B5="","",IFERROR(VLOOKUP(B5,Journals!$A:$B,2,FALSE),IFERROR(VLOOKUP(B5,'ABDC list'!$A:$B,2,FALSE),""))) | H5: =IF(OR(F5="",E5="Planned"),"",IF(G5<>"",G5-F5,TODAY()-F5)) | P5: =IF(E5="Under review",COUNTIFS($E:$E,"Under review",$F:$F,"<"&F5)+COUNTIFS($E$1:E5,"Under review",$F$1:F5,F5),"") | Q5: =IF(B5="","",A5&"|"&E5)
C6: =IF(B6="","",IFERROR(VLOOKUP(B6,Journals!$A:$B,2,FALSE),IFERROR(VLOOKUP(B6,'ABDC list'!$A:$B,2,FALSE),""))) | H6: =IF(OR(F6="",E6="Planned"),"",IF(G6<>"",G6-F6,TODAY()-F6)) | P6: =IF(E6="Under review",COUNTIFS($E:$E,"Under review",$F:$F,"<"&F6)+COUNTIFS($E$1:E6,"Under review",$F$1:F6,F6),"") | Q6: =IF(B6="","",A6&"|"&E6)
C7: =IF(B7="","",IFERROR(VLOOKUP(B7,Journals!$A:$B,2,FALSE),IFERROR(VLOOKUP(B7,'ABDC list'!$A:$B,2,FALSE),""))) | H7: =IF(OR(F7="",E7="Planned"),"",IF(G7<>"",G7-F7,TODAY()-F7)) | P7: =IF(E7="Under review",COUNTIFS($E:$E,"Under review",$F:$F,"<"&F7)+COUNTIFS($E$1:E7,"Under review",$F$1:F7,F7),"") | Q7: =IF(B7="","",A7&"|"&E7)
C8: =IF(B8="","",IFERROR(VLOOKUP(B8,Journals!$A:$B,2,FALSE),IFERROR(VLOOKUP(B8,'ABDC list'!$A:$B,2,FALSE),""))) | H8: =IF(OR(F8="",E8="Planned"),"",IF(G8<>"",G8-F8,TODAY()-F8)) | P8: =IF(E8="Under review",COUNTIFS($E:$E,"Under review",$F:$F,"<"&F8)+COUNTIFS($E$1:E8,"Under review",$F$1:F8,F8),"") | Q8: =IF(B8="","",A8&"|"&E8)
C9: =IF(B9="","",IFERROR(VLOOKUP(B9,Journals!$A:$B,2,FALSE),IFERROR(VLOOKUP(B9,'ABDC list'!$A:$B,2,FALSE),""))) | H9: =IF(OR(F9="",E9="Planned"),"",IF(G9<>"",G9-F9,TODAY()-F9)) | P9: =IF(E9="Under review",COUNTIFS($E:$E,"Under review",$F:$F,"<"&F9)+COUNTIFS($E$1:E9,"Under review",$F$1:F9,F9),"") | Q9: =IF(B9="","",A9&"|"&E9)
C10: =IF(B10="","",IFERROR(VLOOKUP(B10,Journals!$A:$B,2,FALSE),IFERROR(VLOOKUP(B10,'ABDC list'!$A:$B,2,FALSE),""))) | H10: =IF(OR(F10="",E10="Planned"),"",IF(G10<>"",G10-F10,TODAY()-F10)) | P10: =IF(E10="Under review",COUNTIFS($E:$E,"Under review",$F:$F,"<"&F10)+COUNTIFS($E$1:E10,"Under review",$F$1:F10,F10),"") | Q10: =IF(B10="","",A10&"|"&E10)
C11: =IF(B11="","",IFERROR(VLOOKUP(B11,Journals!$A:$B,2,FALSE),IFERROR(VLOOKUP(B11,'ABDC list'!$A:$B,2,FALSE),""))) | H11: =IF(OR(F11="",E11="Planned"),"",IF(G11<>"",G11-F11,TODAY()-F11)) | P11: =IF(E11="Under review",COUNTIFS($E:$E,"Under review",$F:$F,"<"&F11)+COUNTIFS($E$1:E11,"Under review",$F$1:F11,F11),"") | Q11: =IF(B11="","",A11&"|"&E11)
C12: =IF(B12="","",IFERROR(VLOOKUP(B12,Journals!$A:$B,2,FALSE),IFERROR(VLOOKUP(B12,'ABDC list'!$A:$B,2,FALSE),""))) | H12: =IF(OR(F12="",E12="Planned"),"",IF(G12<>"",G12-F12,TODAY()-F12)) | P12: =IF(E12="Under review",COUNTIFS($E:$E,"Under review",$F:$F,"<"&F12)+COUNTIFS($E$1:E12,"Under review",$F$1:F12,F12),"") | Q12: =IF(B12="","",A12&"|"&E12)
C13: =IF(B13="","",IFERROR(VLOOKUP(B13,Journals!$A:$B,2,FALSE),IFERROR(VLOOKUP(B13,'ABDC list'!$A:$B,2,FALSE),""))) | H13: =IF(OR(F13="",E13="Planned"),"",IF(G13<>"",G13-F13,TODAY()-F13)) | P13: =IF(E13="Under review",COUNTIFS($E:$E,"Under review",$F:$F,"<"&F13)+COUNTIFS($E$1:E13,"Under review",$F$1:F13,F13),"") | Q13: =IF(B13="","",A13&"|"&E13)
... C401: =IF(B401="","",IFERROR(VLOOKUP(B401,Journals!$A:$B,2,FALSE),IFERROR(VLOOKUP(B401,'ABDC list'!$A:$B,2,FALSE),""))) | H401: =IF(OR(F401="",E401="Planned"),"",IF(G401<>"",G401-F401,TODAY()-F401)) | P401: =IF(E401="Under review",COUNTIFS($E:$E,"Under review",$F:$F,"<"&F401)+COUNTIFS($E$1:E401,"Under review",$F$1:F401,F401),"") | Q401: =IF(B401="","",A401&"|"&E401)

Sheet Papers
A1: Paper | B1: Title | C1: Authors | D1: Type | E1: Override | F1: Notes | G1: Stage | H1: Current journal | I1: Sent | J1: Rejections | K1: Next in queue | L1: Suggested next journals | M1: App ID | N1: Updated | O1: wait rank | P1: Approach
G2: =IF(A2="","",IF(E2<>"",E2,IF(COUNTIFS(Submissions!$A:$A,A2,Submissions!$E:$E,"Accepted")>0,"Accepted",IF(COUNTIFS(Submissions!$A:$A,A2,Submissions!$E:$E,"Revision requested")>0,"Revision due",IF(COUNTIFS(Submissions!$A:$A,A2,Submissions!$E:$E,"Under review")>0,"Under review",IF(I2>0,"Needs resubmission","Not yet submitted")))))) | H2: =IF(A2="","",IFERROR(INDEX(Submissions!$B:$B,MATCH(A2&"|Under review",Submissions!$Q:$Q,0)),"")) | I2: =IF(A2="","",COUNTIFS(Submissions!$A:$A,A2,Submissions!$B:$B,"<>",Submissions!$E:$E,"<>Planned")) | J2: =IF(A2="","",COUNTIFS(Submissions!$A:$A,A2,Submissions!$E:$E,"Rejected")) | K2: =IF(A2="","",IFERROR(INDEX(Submissions!$B:$B,MATCH(A2&"|Planned",Submissions!$Q:$Q,0)),"")) | O2: =IF(OR(G2="Revision due",G2="Needs resubmission",G2="Not yet submitted"),COUNTIF($G$2:$G$200,"Revision due")*(G2<>"Revision due")+COUNTIF($G$2:$G$200,"Needs resubmission")*(G2="Not yet submitted")+COUNTIFS($G$2:G2,G2),"")
G3: =IF(A3="","",IF(E3<>"",E3,IF(COUNTIFS(Submissions!$A:$A,A3,Submissions!$E:$E,"Accepted")>0,"Accepted",IF(COUNTIFS(Submissions!$A:$A,A3,Submissions!$E:$E,"Revision requested")>0,"Revision due",IF(COUNTIFS(Submissions!$A:$A,A3,Submissions!$E:$E,"Under review")>0,"Under review",IF(I3>0,"Needs resubmission","Not yet submitted")))))) | H3: =IF(A3="","",IFERROR(INDEX(Submissions!$B:$B,MATCH(A3&"|Under review",Submissions!$Q:$Q,0)),"")) | I3: =IF(A3="","",COUNTIFS(Submissions!$A:$A,A3,Submissions!$B:$B,"<>",Submissions!$E:$E,"<>Planned")) | J3: =IF(A3="","",COUNTIFS(Submissions!$A:$A,A3,Submissions!$E:$E,"Rejected")) | K3: =IF(A3="","",IFERROR(INDEX(Submissions!$B:$B,MATCH(A3&"|Planned",Submissions!$Q:$Q,0)),"")) | O3: =IF(OR(G3="Revision due",G3="Needs resubmission",G3="Not yet submitted"),COUNTIF($G$2:$G$200,"Revision due")*(G3<>"Revision due")+COUNTIF($G$2:$G$200,"Needs resubmission")*(G3="Not yet submitted")+COUNTIFS($G$2:G3,G3),"")
G4: =IF(A4="","",IF(E4<>"",E4,IF(COUNTIFS(Submissions!$A:$A,A4,Submissions!$E:$E,"Accepted")>0,"Accepted",IF(COUNTIFS(Submissions!$A:$A,A4,Submissions!$E:$E,"Revision requested")>0,"Revision due",IF(COUNTIFS(Submissions!$A:$A,A4,Submissions!$E:$E,"Under review")>0,"Under review",IF(I4>0,"Needs resubmission","Not yet submitted")))))) | H4: =IF(A4="","",IFERROR(INDEX(Submissions!$B:$B,MATCH(A4&"|Under review",Submissions!$Q:$Q,0)),"")) | I4: =IF(A4="","",COUNTIFS(Submissions!$A:$A,A4,Submissions!$B:$B,"<>",Submissions!$E:$E,"<>Planned")) | J4: =IF(A4="","",COUNTIFS(Submissions!$A:$A,A4,Submissions!$E:$E,"Rejected")) | K4: =IF(A4="","",IFERROR(INDEX(Submissions!$B:$B,MATCH(A4&"|Planned",Submissions!$Q:$Q,0)),"")) | O4: =IF(OR(G4="Revision due",G4="Needs resubmission",G4="Not yet submitted"),COUNTIF($G$2:$G$200,"Revision due")*(G4<>"Revision due")+COUNTIF($G$2:$G$200,"Needs resubmission")*(G4="Not yet submitted")+COUNTIFS($G$2:G4,G4),"")
G5: =IF(A5="","",IF(E5<>"",E5,IF(COUNTIFS(Submissions!$A:$A,A5,Submissions!$E:$E,"Accepted")>0,"Accepted",IF(COUNTIFS(Submissions!$A:$A,A5,Submissions!$E:$E,"Revision requested")>0,"Revision due",IF(COUNTIFS(Submissions!$A:$A,A5,Submissions!$E:$E,"Under review")>0,"Under review",IF(I5>0,"Needs resubmission","Not yet submitted")))))) | H5: =IF(A5="","",IFERROR(INDEX(Submissions!$B:$B,MATCH(A5&"|Under review",Submissions!$Q:$Q,0)),"")) | I5: =IF(A5="","",COUNTIFS(Submissions!$A:$A,A5,Submissions!$B:$B,"<>",Submissions!$E:$E,"<>Planned")) | J5: =IF(A5="","",COUNTIFS(Submissions!$A:$A,A5,Submissions!$E:$E,"Rejected")) | K5: =IF(A5="","",IFERROR(INDEX(Submissions!$B:$B,MATCH(A5&"|Planned",Submissions!$Q:$Q,0)),"")) | O5: =IF(OR(G5="Revision due",G5="Needs resubmission",G5="Not yet submitted"),COUNTIF($G$2:$G$200,"Revision due")*(G5<>"Revision due")+COUNTIF($G$2:$G$200,"Needs resubmission")*(G5="Not yet submitted")+COUNTIFS($G$2:G5,G5),"")
G6: =IF(A6="","",IF(E6<>"",E6,IF(COUNTIFS(Submissions!$A:$A,A6,Submissions!$E:$E,"Accepted")>0,"Accepted",IF(COUNTIFS(Submissions!$A:$A,A6,Submissions!$E:$E,"Revision requested")>0,"Revision due",IF(COUNTIFS(Submissions!$A:$A,A6,Submissions!$E:$E,"Under review")>0,"Under review",IF(I6>0,"Needs resubmission","Not yet submitted")))))) | H6: =IF(A6="","",IFERROR(INDEX(Submissions!$B:$B,MATCH(A6&"|Under review",Submissions!$Q:$Q,0)),"")) | I6: =IF(A6="","",COUNTIFS(Submissions!$A:$A,A6,Submissions!$B:$B,"<>",Submissions!$E:$E,"<>Planned")) | J6: =IF(A6="","",COUNTIFS(Submissions!$A:$A,A6,Submissions!$E:$E,"Rejected")) | K6: =IF(A6="","",IFERROR(INDEX(Submissions!$B:$B,MATCH(A6&"|Planned",Submissions!$Q:$Q,0)),"")) | O6: =IF(OR(G6="Revision due",G6="Needs resubmission",G6="Not yet submitted"),COUNTIF($G$2:$G$200,"Revision due")*(G6<>"Revision due")+COUNTIF($G$2:$G$200,"Needs resubmission")*(G6="Not yet submitted")+COUNTIFS($G$2:G6,G6),"")
G7: =IF(A7="","",IF(E7<>"",E7,IF(COUNTIFS(Submissions!$A:$A,A7,Submissions!$E:$E,"Accepted")>0,"Accepted",IF(COUNTIFS(Submissions!$A:$A,A7,Submissions!$E:$E,"Revision requested")>0,"Revision due",IF(COUNTIFS(Submissions!$A:$A,A7,Submissions!$E:$E,"Under review")>0,"Under review",IF(I7>0,"Needs resubmission","Not yet submitted")))))) | H7: =IF(A7="","",IFERROR(INDEX(Submissions!$B:$B,MATCH(A7&"|Under review",Submissions!$Q:$Q,0)),"")) | I7: =IF(A7="","",COUNTIFS(Submissions!$A:$A,A7,Submissions!$B:$B,"<>",Submissions!$E:$E,"<>Planned")) | J7: =IF(A7="","",COUNTIFS(Submissions!$A:$A,A7,Submissions!$E:$E,"Rejected")) | K7: =IF(A7="","",IFERROR(INDEX(Submissions!$B:$B,MATCH(A7&"|Planned",Submissions!$Q:$Q,0)),"")) | O7: =IF(OR(G7="Revision due",G7="Needs resubmission",G7="Not yet submitted"),COUNTIF($G$2:$G$200,"Revision due")*(G7<>"Revision due")+COUNTIF($G$2:$G$200,"Needs resubmission")*(G7="Not yet submitted")+COUNTIFS($G$2:G7,G7),"")
G8: =IF(A8="","",IF(E8<>"",E8,IF(COUNTIFS(Submissions!$A:$A,A8,Submissions!$E:$E,"Accepted")>0,"Accepted",IF(COUNTIFS(Submissions!$A:$A,A8,Submissions!$E:$E,"Revision requested")>0,"Revision due",IF(COUNTIFS(Submissions!$A:$A,A8,Submissions!$E:$E,"Under review")>0,"Under review",IF(I8>0,"Needs resubmission","Not yet submitted")))))) | H8: =IF(A8="","",IFERROR(INDEX(Submissions!$B:$B,MATCH(A8&"|Under review",Submissions!$Q:$Q,0)),"")) | I8: =IF(A8="","",COUNTIFS(Submissions!$A:$A,A8,Submissions!$B:$B,"<>",Submissions!$E:$E,"<>Planned")) | J8: =IF(A8="","",COUNTIFS(Submissions!$A:$A,A8,Submissions!$E:$E,"Rejected")) | K8: =IF(A8="","",IFERROR(INDEX(Submissions!$B:$B,MATCH(A8&"|Planned",Submissions!$Q:$Q,0)),"")) | O8: =IF(OR(G8="Revision due",G8="Needs resubmission",G8="Not yet submitted"),COUNTIF($G$2:$G$200,"Revision due")*(G8<>"Revision due")+COUNTIF($G$2:$G$200,"Needs resubmission")*(G8="Not yet submitted")+COUNTIFS($G$2:G8,G8),"")
G9: =IF(A9="","",IF(E9<>"",E9,IF(COUNTIFS(Submissions!$A:$A,A9,Submissions!$E:$E,"Accepted")>0,"Accepted",IF(COUNTIFS(Submissions!$A:$A,A9,Submissions!$E:$E,"Revision requested")>0,"Revision due",IF(COUNTIFS(Submissions!$A:$A,A9,Submissions!$E:$E,"Under review")>0,"Under review",IF(I9>0,"Needs resubmission","Not yet submitted")))))) | H9: =IF(A9="","",IFERROR(INDEX(Submissions!$B:$B,MATCH(A9&"|Under review",Submissions!$Q:$Q,0)),"")) | I9: =IF(A9="","",COUNTIFS(Submissions!$A:$A,A9,Submissions!$B:$B,"<>",Submissions!$E:$E,"<>Planned")) | J9: =IF(A9="","",COUNTIFS(Submissions!$A:$A,A9,Submissions!$E:$E,"Rejected")) | K9: =IF(A9="","",IFERROR(INDEX(Submissions!$B:$B,MATCH(A9&"|Planned",Submissions!$Q:$Q,0)),"")) | O9: =IF(OR(G9="Revision due",G9="Needs resubmission",G9="Not yet submitted"),COUNTIF($G$2:$G$200,"Revision due")*(G9<>"Revision due")+COUNTIF($G$2:$G$200,"Needs resubmission")*(G9="Not yet submitted")+COUNTIFS($G$2:G9,G9),"")
G10: =IF(A10="","",IF(E10<>"",E10,IF(COUNTIFS(Submissions!$A:$A,A10,Submissions!$E:$E,"Accepted")>0,"Accepted",IF(COUNTIFS(Submissions!$A:$A,A10,Submissions!$E:$E,"Revision requested")>0,"Revision due",IF(COUNTIFS(Submissions!$A:$A,A10,Submissions!$E:$E,"Under review")>0,"Under review",IF(I10>0,"Needs resubmission","Not yet submitted")))))) | H10: =IF(A10="","",IFERROR(INDEX(Submissions!$B:$B,MATCH(A10&"|Under review",Submissions!$Q:$Q,0)),"")) | I10: =IF(A10="","",COUNTIFS(Submissions!$A:$A,A10,Submissions!$B:$B,"<>",Submissions!$E:$E,"<>Planned")) | J10: =IF(A10="","",COUNTIFS(Submissions!$A:$A,A10,Submissions!$E:$E,"Rejected")) | K10: =IF(A10="","",IFERROR(INDEX(Submissions!$B:$B,MATCH(A10&"|Planned",Submissions!$Q:$Q,0)),"")) | O10: =IF(OR(G10="Revision due",G10="Needs resubmission",G10="Not yet submitted"),COUNTIF($G$2:$G$200,"Revision due")*(G10<>"Revision due")+COUNTIF($G$2:$G$200,"Needs resubmission")*(G10="Not yet submitted")+COUNTIFS($G$2:G10,G10),"")
G11: =IF(A11="","",IF(E11<>"",E11,IF(COUNTIFS(Submissions!$A:$A,A11,Submissions!$E:$E,"Accepted")>0,"Accepted",IF(COUNTIFS(Submissions!$A:$A,A11,Submissions!$E:$E,"Revision requested")>0,"Revision due",IF(COUNTIFS(Submissions!$A:$A,A11,Submissions!$E:$E,"Under review")>0,"Under review",IF(I11>0,"Needs resubmission","Not yet submitted")))))) | H11: =IF(A11="","",IFERROR(INDEX(Submissions!$B:$B,MATCH(A11&"|Under review",Submissions!$Q:$Q,0)),"")) | I11: =IF(A11="","",COUNTIFS(Submissions!$A:$A,A11,Submissions!$B:$B,"<>",Submissions!$E:$E,"<>Planned")) | J11: =IF(A11="","",COUNTIFS(Submissions!$A:$A,A11,Submissions!$E:$E,"Rejected")) | K11: =IF(A11="","",IFERROR(INDEX(Submissions!$B:$B,MATCH(A11&"|Planned",Submissions!$Q:$Q,0)),"")) | O11: =IF(OR(G11="Revision due",G11="Needs resubmission",G11="Not yet submitted"),COUNTIF($G$2:$G$200,"Revision due")*(G11<>"Revision due")+COUNTIF($G$2:$G$200,"Needs resubmission")*(G11="Not yet submitted")+COUNTIFS($G$2:G11,G11),"")
G12: =IF(A12="","",IF(E12<>"",E12,IF(COUNTIFS(Submissions!$A:$A,A12,Submissions!$E:$E,"Accepted")>0,"Accepted",IF(COUNTIFS(Submissions!$A:$A,A12,Submissions!$E:$E,"Revision requested")>0,"Revision due",IF(COUNTIFS(Submissions!$A:$A,A12,Submissions!$E:$E,"Under review")>0,"Under review",IF(I12>0,"Needs resubmission","Not yet submitted")))))) | H12: =IF(A12="","",IFERROR(INDEX(Submissions!$B:$B,MATCH(A12&"|Under review",Submissions!$Q:$Q,0)),"")) | I12: =IF(A12="","",COUNTIFS(Submissions!$A:$A,A12,Submissions!$B:$B,"<>",Submissions!$E:$E,"<>Planned")) | J12: =IF(A12="","",COUNTIFS(Submissions!$A:$A,A12,Submissions!$E:$E,"Rejected")) | K12: =IF(A12="","",IFERROR(INDEX(Submissions!$B:$B,MATCH(A12&"|Planned",Submissions!$Q:$Q,0)),"")) | O12: =IF(OR(G12="Revision due",G12="Needs resubmission",G12="Not yet submitted"),COUNTIF($G$2:$G$200,"Revision due")*(G12<>"Revision due")+COUNTIF($G$2:$G$200,"Needs resubmission")*(G12="Not yet submitted")+COUNTIFS($G$2:G12,G12),"")
G13: =IF(A13="","",IF(E13<>"",E13,IF(COUNTIFS(Submissions!$A:$A,A13,Submissions!$E:$E,"Accepted")>0,"Accepted",IF(COUNTIFS(Submissions!$A:$A,A13,Submissions!$E:$E,"Revision requested")>0,"Revision due",IF(COUNTIFS(Submissions!$A:$A,A13,Submissions!$E:$E,"Under review")>0,"Under review",IF(I13>0,"Needs resubmission","Not yet submitted")))))) | H13: =IF(A13="","",IFERROR(INDEX(Submissions!$B:$B,MATCH(A13&"|Under review",Submissions!$Q:$Q,0)),"")) | I13: =IF(A13="","",COUNTIFS(Submissions!$A:$A,A13,Submissions!$B:$B,"<>",Submissions!$E:$E,"<>Planned")) | J13: =IF(A13="","",COUNTIFS(Submissions!$A:$A,A13,Submissions!$E:$E,"Rejected")) | K13: =IF(A13="","",IFERROR(INDEX(Submissions!$B:$B,MATCH(A13&"|Planned",Submissions!$Q:$Q,0)),"")) | O13: =IF(OR(G13="Revision due",G13="Needs resubmission",G13="Not yet submitted"),COUNTIF($G$2:$G$200,"Revision due")*(G13<>"Revision due")+COUNTIF($G$2:$G$200,"Needs resubmission")*(G13="Not yet submitted")+COUNTIFS($G$2:G13,G13),"")
... G200: =IF(A200="","",IF(E200<>"",E200,IF(COUNTIFS(Submissions!$A:$A,A200,Submissions!$E:$E,"Accepted")>0,"Accepted",IF(COUNTIFS(Submissions!$A:$A,A200,Submissions!$E:$E,"Revision requested")>0,"Revision due",IF(COUNTIFS(Submissions!$A:$A,A200,Submissions!$E:$E,"Under review")>0,"Under review",IF(I200>0,"Needs resubmission","Not yet submitted")))))) | H200: =IF(A200="","",IFERROR(INDEX(Submissions!$B:$B,MATCH(A200&"|Under review",Submissions!$Q:$Q,0)),"")) | I200: =IF(A200="","",COUNTIFS(Submissions!$A:$A,A200,Submissions!$B:$B,"<>",Submissions!$E:$E,"<>Planned")) | J200: =IF(A200="","",COUNTIFS(Submissions!$A:$A,A200,Submissions!$E:$E,"Rejected")) | K200: =IF(A200="","",IFERROR(INDEX(Submissions!$B:$B,MATCH(A200&"|Planned",Submissions!$Q:$Q,0)),"")) | O200: =IF(OR(G200="Revision due",G200="Needs resubmission",G200="Not yet submitted"),COUNTIF($G$2:$G$200,"Revision due")*(G200<>"Revision due")+COUNTIF($G$2:$G$200,"Needs resubmission")*(G200="Not yet submitted")+COUNTIFS($G$2:G200,G200),"")

Sheet Journals
A1: Journal | B1: ABDC 2025 | C1: Name on ABDC list (if different) | D1: ABDC 2022 (if different) | E1: Other rating / index | F1: Login link | G1: Editorial office email | H1: Notes
B2: =IF(A2="","",IFERROR(VLOOKUP(IF(C2<>"",C2,A2),'ABDC list'!$A:$B,2,FALSE),"Not listed"))
B3: =IF(A3="","",IFERROR(VLOOKUP(IF(C3<>"",C3,A3),'ABDC list'!$A:$B,2,FALSE),"Not listed"))
B4: =IF(A4="","",IFERROR(VLOOKUP(IF(C4<>"",C4,A4),'ABDC list'!$A:$B,2,FALSE),"Not listed"))
B5: =IF(A5="","",IFERROR(VLOOKUP(IF(C5<>"",C5,A5),'ABDC list'!$A:$B,2,FALSE),"Not listed"))
B6: =IF(A6="","",IFERROR(VLOOKUP(IF(C6<>"",C6,A6),'ABDC list'!$A:$B,2,FALSE),"Not listed"))
B7: =IF(A7="","",IFERROR(VLOOKUP(IF(C7<>"",C7,A7),'ABDC list'!$A:$B,2,FALSE),"Not listed"))
B8: =IF(A8="","",IFERROR(VLOOKUP(IF(C8<>"",C8,A8),'ABDC list'!$A:$B,2,FALSE),"Not listed"))
B9: =IF(A9="","",IFERROR(VLOOKUP(IF(C9<>"",C9,A9),'ABDC list'!$A:$B,2,FALSE),"Not listed"))
B10: =IF(A10="","",IFERROR(VLOOKUP(IF(C10<>"",C10,A10),'ABDC list'!$A:$B,2,FALSE),"Not listed"))
B11: =IF(A11="","",IFERROR(VLOOKUP(IF(C11<>"",C11,A11),'ABDC list'!$A:$B,2,FALSE),"Not listed"))
B12: =IF(A12="","",IFERROR(VLOOKUP(IF(C12<>"",C12,A12),'ABDC list'!$A:$B,2,FALSE),"Not listed"))
B13: =IF(A13="","",IFERROR(VLOOKUP(IF(C13<>"",C13,A13),'ABDC list'!$A:$B,2,FALSE),"Not listed"))
... B400: =IF(A400="","",IFERROR(VLOOKUP(IF(C400<>"",C400,A400),'ABDC list'!$A:$B,2,FALSE),"Not listed"))

Sheet ABDC list
A1: Journal Title | B1: 2025 rating | C1: FoR | D1: Publisher | F1: Source: ABDC Journal Quality List 2025 (v3, current to September 2026), abdc.edu.au
A2: 4OR | B2: B | C2: 3599 | D2: Springer Nature
A3: AACE International Transactions | B3: B | C3: 3599 | D3: AACE International
A4: Abacus | B4: A | C4: 3501 | D4: Wiley-Blackwell Publishing
A5: Academia Economic Papers | B5: C | C5: 3801 | D5: Institute of Economics, Academia Sinica
A6: Academy of Management Annals | B6: A* | C6: 3507 | D6: Academy of Management
A7: Academy of Management Discoveries | B7: A* | C7: 3507 | D7: Academy of Management
A8: Academy of Management Journal | B8: A* | C8: 3507 | D8: Academy of Management
A9: Academy of Management Learning and Education | B9: A* | C9: 3507 | D9: Academy of Management
A10: Academy of Management Perspectives | B10: A | C10: 3507 | D10: Academy of Management
A11: Academy of Management Review | B11: A* | C11: 3507 | D11: Academy of Management
A12: Academy of Marketing Studies Journal | B12: B | C12: 3506 | D12: Allied Business Academies
A13: Accident Analysis and Prevention | B13: A* | C13: 3509 | D13: Elsevier
... A354: Business Strategy Review | B354: B | C354: 3507 | D354: Wiley-Blackwell Publishing
A355: Cadernos de Pos-Graduacao em Direito Politico e Economico | B355: C | C355: 3801
A356: California Management Review | B356: A | C356: 3507 | D356: Sage Publications
A357: Cambridge Journal of Economics | B357: A | C357: 3801 | D357: Oxford University Press
A358: Cambridge Journal of Regions, Economy and Society | B358: B | C358: 3801 | D358: Oxford University Press
A359: Cambridge Law Journal | B359: A* | C359: 4801 | D359: Cambridge University Press
A360: Canadian Bar Review | B360: B | C360: 4801 | D360: Canadian Bar Association
A361: Canadian Business Law Journal | B361: A | C361: 4801 | D361: Canada Law Book
A362: Canadian Journal of Administrative Sciences / Revue Canadienne des Sciences de l Administration | B362: B | C362: 3507 | D362: Wiley-Blackwell Publishing
A363: Canadian Journal of Agricultural Economics / Revue Canadienne d Agroeconomie | B363: A | C363: 3801 | D363: Wiley-Blackwell Publishing
A364: Canadian Journal of Development Studies / Revue canadienne d'etudes du developpement | B364: B | C364: 3801 | D364: Taylor & Francis Online
A365: Canadian Journal of Economics / Revue Canadienne D'Economique | B365: A | C365: 3801 | D365: Wiley-Blackwell Publishing
A366: Canadian Journal of Marketing Research | B366: C | C366: 3506 | D366: Marketing Research and Intelligence Association
A367: Canadian Journal of Statistics | B367: A | C367: 4905 | D367: Wiley-Blackwell Publishing
... A1114: International Journal of Selection and Assessment | B1114: A | C1114: 3505 | D1114: Wiley-Blackwell Publishing
A1115: International Journal of Small and Medium Enterprises | B1115: C | C1115: 3507
A1116: International Journal of Social and Humanistic Computing | B1116: C | C1116: 4609 | D1116: Inderscience Enterprises Ltd.
A1117: International Journal of Social Economics | B1117: B | C1117: 3899 | D1117: Emerald Group Publishing
A1118: International Journal of Social Research Methodology | B1118: B | C1118: 3507 | D1118: Taylor & Francis Online
A1119: International Journal of Sociology and Social Policy | B1119: B | C1119: 3507 | D1119: Emerald Group Publishing
A1120: International Journal of Spa and Wellness | B1120: C | C1120: 3508 | D1120: Taylor & Francis Online
A1121: International Journal of Sport Communication | B1121: B | C1121: 3504 | D1121: Human Kinetics Publishers, Inc.
A1122: International Journal of Sport Finance | B1122: C | C1122: 3504 | D1122: Sage Publications
A1123: International Journal of Sport Management | B1123: B | C1123: 3504 | D1123: American Press, Boston
A1124: International Journal of Sport Policy and Politics | B1124: C | C1124: 3504 | D1124: Taylor & Francis Online
A1125: International Journal of Sport Psychology | B1125: B | C1125: 3504 | D1125: Edizioni Luigi Pozzi, Rome
A1126: International Journal of Sports Management and Marketing | B1126: B | C1126: 3506 | D1126: Inderscience Enterprises Ltd.
...
